Workbook
Name 费用种类列表: [1]费用种类列表!$A$2:$A$5211

Sheet 过机服务商重量差
A1: 运单号 | B1: 服务商单号 | C1: 渠道转单号 | D1: 销售产品 | E1: 产品组 | F1: 服务渠道 | G1: 服务渠道客服 | H1: 客户简称 | I1: 业务员 | J1: 出货实重 | K1: 出货材积重 | L1: 出货计费重 | M1: 服务商计费重 | N1: 差值
A2: QS0131-MX | B2: ICBU00000932919 | C2: 1ZG3325W0416448603 | D2: OK-FDX-DHL-TNT | E2: 非主营 | F2: OK-FDX-DHL-TNT | G2: 玉麒麟 | I2: 小飞侠 | J2: 1.87 | K2: 4.059 | L2: 3.5 | M2: 4.5 | N2: 1
A3: TL0131-NL | B3: ICBU00000932943 | C3: 1Z4W260E0409673969 | D3: OK-UPS红单 | E3: 非主营 | F3: OK-UPS红单 | G3: 玉麒麟 | I3: 小飞侠 | J3: 9.23 | K3: 4.277 | L3: 9.5 | M3: 9.5 | N3: 0
A4: FBA15G65R8GW | B4: ICBU00000932665 | C4: RCD24000759946 | D4: 澳大利亚海派-包税 | E4: 非主营 | F4: 澳大利亚海派-包税 | G4: 小旋风 | I4: 高雨晴 | J4: 105.07 | K4: 0.654 | L4: 0.7 | M4: 0.8 | N4: 0.1
A5: FBA15G65P13K | B5: ICBU00000932701 | C5: RCD24000759947 | D5: 澳大利亚海派-包税 | E5: 非主营 | F5: 澳大利亚海派-包税 | G5: 小旋风 | I5: 高雨晴 | J5: 77.91 | K5: 0.647 | L5: 0.8 | M5: 0.8 | N5: 0
A6: SP260122021 | B6: ICBU00000933108 | D6: 欧洲海派-M | E6: 非主营 | F6: 欧洲海派-M | G6: 张诚 | I6: 马淞浦 | J6: 43.64 | K6: 35.783 | L6: 44 | M6: 44 | N6: 0
A7: SP260129024 | B7: ICBU00000933109 | D7: 欧洲海派-M | E7: 非主营 | F7: 欧洲海派-M | G7: 张诚 | I7: 马淞浦 | J7: 235.02 | K7: 201.12 | L7: 236 | M7: 236 | N7: 0
A8: SP260121227 | B8: ICBU00000933107 | D8: 欧洲海派-M | E8: 非主营 | F8: 欧洲海派-M | G8: 张诚 | I8: 马淞浦 | J8: 76.54 | K8: 55.296 | L8: 77 | M8: 77 | N8: 0
A9: SP260123008 | B9: ICBU00000933118 | D9: 欧洲海派-M | E9: 非主营 | F9: 欧洲海派-M | G9: 张诚 | I9: 马淞浦 | J9: 182.35 | K9: 157.348 | L9: 183 | M9: 183 | N9: 0
A10: SP260122003 | B10: ICBU00000933106 | D10: 欧洲海派-M | E10: 非主营 | F10: 欧洲海派-M | G10: 张诚 | I10: 马淞浦 | J10: 131.67 | K10: 103.47 | L10: 132 | M10: 132 | N10: 0
A11: SP260121220 | B11: ICBU00000932842 | C11: KP | D11: 加拿大海派-JY | E11: 非主营 | F11: 加拿大海派-JY | G11: 风清扬 | I11: 马淞浦 | J11: 66.78 | K11: 51.207 | L11: 67 | M11: 67 | N11: 0
A12: SP260120060 | B12: ICBU00000932975 | C12: KP | D12: 加拿大海派-JY | E12: 非主营 | F12: 加拿大海派-JY | G12: 风清扬 | I12: 马淞浦 | J12: 271.26 | K12: 187.498 | L12: 272 | M12: 272 | N12: 0
A13: SP260122050 | B13: ICBU00000932908 | C13: KP | D13: 加拿大海派-JY | E13: 非主营 | F13: 加拿大海派-JY | G13: 风清扬 | I13: 马淞浦 | J13: 136.99 | K13: 98.223 | L13: 138 | M13: 137 | N13: -1
A14: SP260122007 | B14: ICBU00000933117 | D14: 欧洲海派-M | E14: 非主营 | F14: 欧洲海派-M | G14: 张诚 | I14: 马淞浦 | J14: 124.82 | K14: 115.412 | L14: 125 | M14: 125 | N14: 0
A15: SP260121264 | B15: ICBU00000933138 | D15: 欧洲海派-M | E15: 非主营 | F15: 欧洲海派-M | G15: 张诚 | I15: 马淞浦 | J15: 233.25 | K15: 177.097 | L15: 234 | M15: 234 | N15: 0
A16: SP260121188 | B16: ICBU00000932970 | C16: KP | D16: 加拿大海派-JY | E16: 非主营 | F16: 加拿大海派-JY | G16: 风清扬 | I16: 马淞浦 | J16: 36.3 | K16: 28.373 | L16: 37 | M16: 37 | N16: 0
A17: SP260121174 | B17: ICBU00000932897 | C17: KP | D17: 加拿大海派-JY | E17: 非主营 | F17: 加拿大海派-JY | G17: 风清扬 | I17: 马淞浦 | J17: 25.91 | K17: 22.747 | L17: 26 | M17: 26 | N17: 0
A18: SP260121195 | B18: ICBU00000933111 | D18: 欧洲海派-M | E18: 非主营 | F18: 欧洲海派-M | G18: 张诚 | I18: 马淞浦 | J18: 40.95 | K18: 27.728 | L18: 41 | M18: 41 | N18: 0
A19: SP260121223 | B19: ICBU00000933110 | D19: 欧洲海派-M | E19: 非主营 | F19: 欧洲海派-M | G19: 张诚 | I19: 马淞浦 | J19: 312.72 | K19: 224.327 | L19: 313 | M19: 313 | N19: 0
A20: SP260120043-YYZ7-16 | B20: ICBU00000932894 | C20: KP | D20: 加拿大海派-JY | E20: 非主营 | F20: 加拿大海派-JY | G20: 风清扬 | I20: 马淞浦 | J20: 269 | K20: 200.901 | L20: 270 | M20: 269 | N20: -1
A21: SP260126064-YYZ7-38 | B21: ICBU00000932826 | C21: KP | D21: 加拿大海派-JY | E21: 非主营 | F21: 加拿大海派-JY | G21: 风清扬 | I21: 马淞浦 | J21: 730.44 | K21: 652.894 | L21: 732 | M21: 731 | N21: -1
A22: SP260112003 | B22: ICBU00000933121 | D22: 欧洲海派-M | E22: 非主营 | F22: 欧洲海派-M | G22: 张诚 | I22: 马淞浦 | J22: 633.45 | K22: 431.198 | L22: 634 | M22: 634 | N22: 0
A23: HCLSA0131-6 | B23: ICBU00000932498 | C23: TPL000134937 | D23: 澳大利亚海派-含税-SC | E23: 非主营 | F23: 澳大利亚海派-含税-SC | G23: 小旋风 | I23: 刘申奥 | J23: 36.48 | K23: 22.308 | L23: 37 | M23: 43 | N23: 6
A24: SP260121154 | B24: ICBU00000933112 | D24: 欧洲海派-M | E24: 非主营 | F24: 欧洲海派-M | G24: 张诚 | I24: 马淞浦 | J24: 502.74 | K24: 499.672 | L24: 503 | M24: 503 | N24: 0
A25: YKZXX013102 | B25: ICBU00000932200 | C25: 1ZA06B016832064447 | D25: 欧洲德国清专线 | E25: 非主营 | F25: 欧洲德国清专线 | G25: 小旋风 | I25: 张小雪 | J25: 51.07 | K25: 41.317 | L25: 52 | M25: 52 | N25: 0
A26: TM260131-1CA3 | B26: ICBU00000932388 | C26: 888386607575 | D26: OK-FDX-DHL-TNT | E26: 非主营 | F26: OK-FDX-DHL-TNT | G26: 玉麒麟 | I26: 邓健群 | J26: 0.72 | K26: 0 | L26: 1 | M26: 1 | N26: 0
A27: TM260131-2FR2 | B27: ICBU00000932359 | C27: 1ZA06B016818572639 | D27: 欧洲德国清专线 | E27: 非主营 | F27: 欧洲德国清专线 | G27: 小旋风 | I27: 邓健群 | J27: 29.31 | K27: 20.758 | L27: 30 | M27: 30 | N27: 0
A28: HH233M26 | B28: ICBU00000932242 | C28: 1ZF4K3596816247057 | D28: 欧洲专线-HMC | E28: 非主营 | F28: 欧洲专线-HMC | G28: 帅时莹 | I28: 李娟-业务 | J28: 189.88 | K28: 186.461 | L28: 208 | M28: 208 | N28: 0
A29: RSC3104 | B29: ICBU00000933165 | C29: 1Z0E465J0413832648 | D29: OK-FDX-DHL-TNT | E29: 非主营 | F29: OK-FDX-DHL-TNT | G29: 玉麒麟 | I29: 汪祺 | J29: 9.8 | K29: 6.919 | L29: 10 | M29: 10 | N29: 0
A30: RSC3103 | B30: ICBU00000933199 | C30: 1Z0E465J0419105235 | D30: OK-FDX-DHL-TNT | E30: 非主营 | F30: OK-FDX-DHL-TNT | G30: 玉麒麟 | I30: 汪祺 | J30: 9.83 | K30: 7.88 | L30: 10 | M30: 10 | N30: 0
A31: RSC3102 | B31: ICBU00000933162 | C31: 1Z0E465J0419058000 | D31: OK-FDX-DHL-TNT | E31: 非主营 | F31: OK-FDX-DHL-TNT | G31: 玉麒麟 | I31: 汪祺 | J31: 5.31 | K31: 4.997 | L31: 5.5 | M31: 5.5 | N31: 0
A32: RSC3101 | B32: ICBU00000933159 | C32: 1Z0E465J0415072448 | D32: OK-FDX-DHL-TNT | E32: 非主营 | F32: OK-FDX-DHL-TNT | G32: 玉麒麟 | I32: 汪祺 | J32: 6.37 | K32: 4.191 | L32: 6.5 | M32: 6.5 | N32: 0
A33: QLWJ1781704 | B33: ICBU00000932639 | C33: 1Z0E793D0422717448 | D33: OK-UPS红单 | E33: 非主营 | F33: OK-UPS红单 | G33: 玉麒麟 | I33: 宁春阳 | J33: 50.38 | K33: 52.836 | L33: 52 | M33: 56 | N33: 4
A34: JHZW7312 | B34: ICBU00000931347 | C34: 888384610822 | D34: OK-FDX-DHL-TNT | E34: 非主营 | F34: OK-FDX-DHL-TNT | G34: 玉麒麟 | I34: 宋海周 | J34: 28.04 | K34: 18.262 | L34: 29 | M34: 29 | N34: 0
A35: SH0131-2 | B35: ICBU00000932684 | C35: 1ZHF38642014756797 | D35: 加拿大准时达海派UPS | E35: 非主营 | F35: 加拿大准时达海派UPS | G35: 风清扬 | I35: 小飞侠 | J35: 16.97 | K35: 22.182 | L35: 27 | M35: 23 | N35: -4
A36: JPS20260131002 | B36: ICBU00000932924 | C36: CR431657742DE | D36: HST-UPS 6000 | E36: 非主营 | F36: HST-UPS 6000 | G36: 无崖子 | I36: 柴燕玲 | J36: 7.45 | K36: 9.281 | L36: 7.5 | M36: 9.5 | N36: 2
... A49: LM-056 | B49: ICBU00000932113 | C49: 1Z0R6D926806701789 | D49: 欧洲卡航含税(快递派) | E49: 非主营 | F49: 欧洲卡航含税(快递派） | G49: 007 | I49: 张小雪 | J49: 53.99 | K49: 53.065 | L49: 55 | M49: 54 | N49: -1
A50: YKZXX0131 | B50: ICBU00000932135 | D50: 义乌联邦IE-包税 | E50: 非主营 | F50: 义乌联邦IE-包税 | G50: 无崖子 | I50: 张小雪 | J50: 48.64 | K50: 113.528 | L50: 118 | M50: 122 | N50: 4
A51: HJ25613101 | B51: ICBU00000932738 | C51: 888401830517 | D51: JRGJ-专线 | E51: 非主营 | F51: JRGJ-专线 | G51: 帅时莹 | I51: 李凤 | J51: 69.65 | K51: 72.481 | L51: 82 | M51: 73 | N51: -9
A52: 29G6T9 | B52: ICBU00000933001 | C52: CR431656565DE | D52: HST-UPS 6000 | E52: 非主营 | F52: HST-UPS 6000 | G52: 无崖子 | I52: 李可 | J52: 12.39 | K52: 9.758 | L52: 12.5 | M52: 13 | N52: 0.5
...

Sheet 业务数据统计
A1: 期间 | B1: 渠道客服 | C1: 渠道 | D1: 出货计费重 | E1: 业务占用提成金额 | F1: 是否计算提成 | G1: 客户单号 | H1: 服务商单号 | I1: 渠道转单号 | J1: 销售产品 | K1: 应收运费单价 | L1: 产品组 | M1: 结算员 | N1: 目的国家 | O1: 邮编 | P1: FBA仓库代码 | Q1: 客户 | R1: 客户类型 | S1: 业务员 | T1: 业务员部门 | U1: 前线客服 | V1: 申报总价值 | W1: 货物类型 | X1: 操作状态 | Y1: 中转状态 | Z1: 退件状态 | AA1: 件数 | AB1: 收货实重 | AC1: 收货计费重 | AD1: 收货比重 | AE1: 服务商计费重 | AF1: 应收 | AG1: 实收 | AH1: 应收单价 | AI1: 应付 | AJ1: 实付 | AK1: 毛利 | AL1: 业务员成本 | AM1: 业务员成本单价 | AN1: 业务员毛利 | AO1: 产品部毛利 | AP1: 核销时间 | AQ1: 应收是否锁定 | AR1: 应付是否锁定 | AS1: 结算服务商 | AT1: 业务服务商 | AU1: 服务渠道 | AV1: 收货机构 | AW1: 到货时间 | AX1: 到货总单 | AY1: 出货时间 | AZ1: 出货总单 | BA1: 附加服务 | BB1: 航空主单号 | BC1: 中文品名 | BD1: 自定义备注
A2: =MID(AW2,1,7) -> 2026-01 | B2: =_xlfn.XLOOKUP(G2,过机服务商重量差!A:A,过机服务商重量差!G:G) -> 玉麒麟 | C2: =IF(OR(AO2<0,L2="FBA海运"),"","渠道") -> 渠道 | D2: =ROUND(IF(AND(AO2>=0,Y2="正常走货"),_xlfn.XLOOKUP(G2,过机服务商重量差!A:A,过机服务商重量差!L:L),"0"),2) -> 3.5 | E2: =ROUND(IF(B2="吴敏洁(小旋风)",$D2/提成!$D$4*提成!$E$4,$D2/提成!$D$3*提成!$E$3),2) -> 0.04 | F2: {=IFERROR(LOOKUP(1,0/((B2=名单!B:B)*(VALUE(AW2)>=名单!E:E)*(VALUE(AW2)<=名单!G:G)*(Y2="正常走货")),名单!H:H),"否")} -> 否 | G2: QS0131-MX | H2: 1ZG3325W0416448603 | J2: OK-FDX-DHL-TNT | L2: 非主营 | S2: 小飞侠 | T2: 营销五部 | Y2: 正常走货 | AO2: 118.16 | AW2: 2026-01-31 22:46:57
A3: =MID(AW3,1,7) -> 2026-01 | B3: =_xlfn.XLOOKUP(G3,过机服务商重量差!A:A,过机服务商重量差!G:G) -> 玉麒麟 | C3: =IF(OR(AO3<0,L3="FBA海运"),"","渠道") -> 渠道 | D3: =ROUND(IF(AND(AO3>=0,Y3="正常走货"),_xlfn.XLOOKUP(G3,过机服务商重量差!A:A,过机服务商重量差!L:L),"0"),2) -> 9.5 | E3: =ROUND(IF(B3="小旋风",$D3/提成!$D$4*提成!$E$4,$D3/提成!$D$3*提成!$E$3),2) -> 0.1 | F3: =IFERROR(LOOKUP(1,0/((B3=名单!B:B)*(VALUE(AW3)>=名单!E:E)*(VALUE(AW3)<=名单!G:G)*(Y3="正常走货")),名单!H:H),"否") -> 否 | G3: TL0131-NL | H3: 1Z4W260E0409673969 | J3: OK-UPS红单 | L3: 非主营 | S3: 小飞侠 | T3: 营销五部 | Y3: 正常走货 | AO3: 132.4 | AW3: 2026-01-31 22:46:36
A4: =MID(AW4,1,7) -> 2026-01 | B4: =_xlfn.XLOOKUP(G4,过机服务商重量差!A:A,过机服务商重量差!G:G) -> 小旋风 | C4: =IF(OR(AO4<0,L4="FBA海运"),"","渠道") -> 渠道 | D4: =ROUND(IF(AND(AO4>=0,Y4="正常走货"),_xlfn.XLOOKUP(G4,过机服务商重量差!A:A,过机服务商重量差!L:L),"0"),2) -> 0.7 | E4: =ROUND(IF(B4="小旋风",$D4/提成!$D$4*提成!$E$4,$D4/提成!$D$3*提成!$E$3),2) -> 0.01 | F4: =IFERROR(LOOKUP(1,0/((B4=名单!B:B)*(VALUE(AW4)>=名单!E:E)*(VALUE(AW4)<=名单!G:G)*(Y4="正常走货")),名单!H:H),"否") -> 是 | G4: FBA15G65R8GW | H4: RCD24000759946 | J4: 澳大利亚海派-包税 | L4: 非主营 | S4: 高雨晴 | T4: 营销二部 | Y4: 正常走货 | AO4: 420 | AW4: 2026-01-31 22:45:45
A5: =MID(AW5,1,7) -> 2026-01 | B5: =_xlfn.XLOOKUP(G5,过机服务商重量差!A:A,过机服务商重量差!G:G) -> 小旋风 | C5: =IF(OR(AO5<0,L5="FBA海运"),"","渠道") -> 渠道 | D5: =ROUND(IF(AND(AO5>=0,Y5="正常走货"),_xlfn.XLOOKUP(G5,过机服务商重量差!A:A,过机服务商重量差!L:L),"0"),2) -> 0.8 | E5: =ROUND(IF(B5="小旋风",$D5/提成!$D$4*提成!$E$4,$D5/提成!$D$3*提成!$E$3),2) -> 0.01 | F5: =IFERROR(LOOKUP(1,0/((B5=名单!B:B)*(VALUE(AW5)>=名单!E:E)*(VALUE(AW5)<=名单!G:G)*(Y5="正常走货")),名单!H:H),"否") -> 是 | G5: FBA15G65P13K | H5: RCD24000759947 | J5: 澳大利亚海派-包税 | L5: 非主营 | S5: 高雨晴 | T5: 营销二部 | Y5: 正常走货 | AO5: 800 | AW5: 2026-01-31 22:45:28
A6: =MID(AW6,1,7) -> 2026-01 | B6: =_xlfn.XLOOKUP(G6,过机服务商重量差!A:A,过机服务商重量差!G:G) -> 张诚 | C6: =IF(OR(AO6<0,L6="FBA海运"),"","渠道") -> 渠道 | D6: =ROUND(IF(AND(AO6>=0,Y6="正常走货"),_xlfn.XLOOKUP(G6,过机服务商重量差!A:A,过机服务商重量差!L:L),"0"),2) -> 44 | E6: =ROUND(IF(B6="小旋风",$D6/提成!$D$4*提成!$E$4,$D6/提成!$D$3*提成!$E$3),2) -> 0.44 | F6: =IFERROR(LOOKUP(1,0/((B6=名单!B:B)*(VALUE(AW6)>=名单!E:E)*(VALUE(AW6)<=名单!G:G)*(Y6="正常走货")),名单!H:H),"否") -> 否 | G6: SP260122021 | J6: 欧洲海卡包税-MM | L6: 非主营 | S6: 马淞浦 | T6: 营销一部 | Y6: 正常走货 | AO6: 400 | AW6: 2026-01-31 22:43:03
A7: =MID(AW7,1,7) -> 2026-01 | B7: =_xlfn.XLOOKUP(G7,过机服务商重量差!A:A,过机服务商重量差!G:G) -> 张诚 | C7: =IF(OR(AO7<0,L7="FBA海运"),"","渠道") -> 渠道 | D7: =ROUND(IF(AND(AO7>=0,Y7="正常走货"),_xlfn.XLOOKUP(G7,过机服务商重量差!A:A,过机服务商重量差!L:L),"0"),2) -> 236 | E7: =ROUND(IF(B7="小旋风",$D7/提成!$D$4*提成!$E$4,$D7/提成!$D$3*提成!$E$3),2) -> 2.36 | F7: =IFERROR(LOOKUP(1,0/((B7=名单!B:B)*(VALUE(AW7)>=名单!E:E)*(VALUE(AW7)<=名单!G:G)*(Y7="正常走货")),名单!H:H),"否") -> 否 | G7: SP260129024 | J7: 欧洲海卡包税-MM | L7: 非主营 | S7: 马淞浦 | T7: 营销一部 | Y7: 正常走货 | AO7: 2832 | AW7: 2026-01-31 22:42:39
A8: =MID(AW8,1,7) -> 2026-01 | B8: =_xlfn.XLOOKUP(G8,过机服务商重量差!A:A,过机服务商重量差!G:G) -> 张诚 | C8: =IF(OR(AO8<0,L8="FBA海运"),"","渠道") -> 渠道 | D8: =ROUND(IF(AND(AO8>=0,Y8="正常走货"),_xlfn.XLOOKUP(G8,过机服务商重量差!A:A,过机服务商重量差!L:L),"0"),2) -> 77 | E8: =ROUND(IF(B8="小旋风",$D8/提成!$D$4*提成!$E$4,$D8/提成!$D$3*提成!$E$3),2) -> 0.77 | F8: =IFERROR(LOOKUP(1,0/((B8=名单!B:B)*(VALUE(AW8)>=名单!E:E)*(VALUE(AW8)<=名单!G:G)*(Y8="正常走货")),名单!H:H),"否") -> 否 | G8: SP260121227 | J8: 欧洲海卡包税-MM | L8: 非主营 | S8: 马淞浦 | T8: 营销一部 | Y8: 正常走货 | AO8: 924 | AW8: 2026-01-31 22:42:32
A9: =MID(AW9,1,7) -> 2026-01 | B9: =_xlfn.XLOOKUP(G9,过机服务商重量差!A:A,过机服务商重量差!G:G) -> 张诚 | C9: =IF(OR(AO9<0,L9="FBA海运"),"","渠道") -> 渠道 | D9: =ROUND(IF(AND(AO9>=0,Y9="正常走货"),_xlfn.XLOOKUP(G9,过机服务商重量差!A:A,过机服务商重量差!L:L),"0"),2) -> 183 | E9: =ROUND(IF(B9="小旋风",$D9/提成!$D$4*提成!$E$4,$D9/提成!$D$3*提成!$E$3),2) -> 1.83 | F9: =IFERROR(LOOKUP(1,0/((B9=名单!B:B)*(VALUE(AW9)>=名单!E:E)*(VALUE(AW9)<=名单!G:G)*(Y9="正常走货")),名单!H:H),"否") -> 否 | G9: SP260123008 | J9: 欧洲海卡包税-MM | L9: 非主营 | S9: 马淞浦 | T9: 营销一部 | Y9: 正常走货 | AO9: 2196 | AW9: 2026-01-31 22:40:53
A10: =MID(AW10,1,7) -> 2026-01 | B10: =_xlfn.XLOOKUP(G10,过机服务商重量差!A:A,过机服务商重量差!G:G) -> 张诚 | C10: =IF(OR(AO10<0,L10="FBA海运"),"","渠道") -> 渠道 | D10: =ROUND(IF(AND(AO10>=0,Y10="正常走货"),_xlfn.XLOOKUP(G10,过机服务商重量差!A:A,过机服务商重量差!L:L),"0"),2) -> 132 | E10: =ROUND(IF(B10="小旋风",$D10/提成!$D$4*提成!$E$4,$D10/提成!$D$3*提成!$E$3),2) -> 1.32 | F10: =IFERROR(LOOKUP(1,0/((B10=名单!B:B)*(VALUE(AW10)>=名单!E:E)*(VALUE(AW10)<=名单!G:G)*(Y10="正常走货")),名单!H:H),"否") -> 否 | G10: SP260122003 | J10: 欧洲海卡包税-MM | L10: 非主营 | S10: 马淞浦 | T10: 营销一部 | Y10: 正常走货 | AO10: 1584 | AW10: 2026-01-31 22:39:00
A11: =MID(AW11,1,7) -> 2026-01 | B11: =_xlfn.XLOOKUP(G11,过机服务商重量差!A:A,过机服务商重量差!G:G) -> 风清扬 | C11: =IF(OR(AO11<0,L11="FBA海运"),"","渠道") | D11: =ROUND(IF(AND(AO11>=0,Y11="正常走货"),_xlfn.XLOOKUP(G11,过机服务商重量差!A:A,过机服务商重量差!L:L),"0"),2) -> 0 | E11: =ROUND(IF(B11="小旋风",$D11/提成!$D$4*提成!$E$4,$D11/提成!$D$3*提成!$E$3),2) -> 0 | F11: =IFERROR(LOOKUP(1,0/((B11=名单!B:B)*(VALUE(AW11)>=名单!E:E)*(VALUE(AW11)<=名单!G:G)*(Y11="正常走货")),名单!H:H),"否") -> 是 | G11: SP260121220 | H11: KP | J11: 加拿大海派-JY | L11: 非主营 | S11: 马淞浦 | T11: 营销一部 | Y11: 正常走货 | AO11: -99.5 | AW11: 2026-01-31 22:37:31
A12: =MID(AW12,1,7) -> 2026-01 | B12: =_xlfn.XLOOKUP(G12,过机服务商重量差!A:A,过机服务商重量差!G:G) -> 风清扬 | C12: =IF(OR(AO12<0,L12="FBA海运"),"","渠道") -> 渠道 | D12: =ROUND(IF(AND(AO12>=0,Y12="正常走货"),_xlfn.XLOOKUP(G12,过机服务商重量差!A:A,过机服务商重量差!L:L),"0"),2) -> 272 | E12: =ROUND(IF(B12="小旋风",$D12/提成!$D$4*提成!$E$4,$D12/提成!$D$3*提成!$E$3),2) -> 2.72 | F12: =IFERROR(LOOKUP(1,0/((B12=名单!B:B)*(VALUE(AW12)>=名单!E:E)*(VALUE(AW12)<=名单!G:G)*(Y12="正常走货")),名单!H:H),"否") -> 是 | G12: SP260120060 | H12: KP | J12: 加拿大海派-JY | L12: 非主营 | S12: 马淞浦 | T12: 营销一部 | Y12: 正常走货 | AO12: 126.4 | AW12: 2026-01-31 22:37:02
A13: =MID(AW13,1,7) -> 2026-01 | B13: =_xlfn.XLOOKUP(G13,过机服务商重量差!A:A,过机服务商重量差!G:G) -> 风清扬 | C13: =IF(OR(AO13<0,L13="FBA海运"),"","渠道") -> 渠道 | D13: =ROUND(IF(AND(AO13>=0,Y13="正常走货"),_xlfn.XLOOKUP(G13,过机服务商重量差!A:A,过机服务商重量差!L:L),"0"),2) -> 138 | E13: =ROUND(IF(B13="小旋风",$D13/提成!$D$4*提成!$E$4,$D13/提成!$D$3*提成!$E$3),2) -> 1.38 | F13: =IFERROR(LOOKUP(1,0/((B13=名单!B:B)*(VALUE(AW13)>=名单!E:E)*(VALUE(AW13)<=名单!G:G)*(Y13="正常走货")),名单!H:H),"否") -> 是 | G13: SP260122050 | H13: KP | J13: 加拿大海派-JY | L13: 非主营 | S13: 马淞浦 | T13: 营销一部 | Y13: 正常走货 | AO13: 139.3 | AW13: 2026-01-31 22:36:32
A14: =MID(AW14,1,7) -> 2026-01 | B14: =_xlfn.XLOOKUP(G14,过机服务商重量差!A:A,过机服务商重量差!G:G) -> 张诚 | C14: =IF(OR(AO14<0,L14="FBA海运"),"","渠道") -> 渠道 | D14: =ROUND(IF(AND(AO14>=0,Y14="正常走货"),_xlfn.XLOOKUP(G14,过机服务商重量差!A:A,过机服务商重量差!L:L),"0"),2) -> 125 | E14: =ROUND(IF(B14="小旋风",$D14/提成!$D$4*提成!$E$4,$D14/提成!$D$3*提成!$E$3),2) -> 1.25 | F14: =IFERROR(LOOKUP(1,0/((B14=名单!B:B)*(VALUE(AW14)>=名单!E:E)*(VALUE(AW14)<=名单!G:G)*(Y14="正常走货")),名单!H:H),"否") -> 否 | G14: SP260122007 | J14: 欧洲海卡包税-MM | L14: 非主营 | S14: 马淞浦 | T14: 营销一部 | Y14: 正常走货 | AO14: 1562.5 | AW14: 2026-01-31 22:31:06
A15: =MID(AW15,1,7) -> 2026-01 | B15: =_xlfn.XLOOKUP(G15,过机服务商重量差!A:A,过机服务商重量差!G:G) -> 张诚 | C15: =IF(OR(AO15<0,L15="FBA海运"),"","渠道") -> 渠道 | D15: =ROUND(IF(AND(AO15>=0,Y15="正常走货"),_xlfn.XLOOKUP(G15,过机服务商重量差!A:A,过机服务商重量差!L:L),"0"),2) -> 234 | E15: =ROUND(IF(B15="小旋风",$D15/提成!$D$4*提成!$E$4,$D15/提成!$D$3*提成!$E$3),2) -> 2.34 | F15: {=IFERROR(LOOKUP(1,0/((B15=名单!B:B)*(VALUE(AW15)>=名单!E:E)*(VALUE(AW15)<=名单!G:G)*(Y15="正常走货")),名单!H:H),"否")} -> 否 | G15: SP260121264 | J15: 欧洲海卡包税-MM | L15: 非主营 | S15: 马淞浦 | T15: 营销一部 | Y15: 正常走货 | AO15: 2925 | AW15: 2026-01-31 22:26:23
A16: =MID(AW16,1,7) -> 2026-01 | B16: =_xlfn.XLOOKUP(G16,过机服务商重量差!A:A,过机服务商重量差!G:G) -> 风清扬 | C16: =IF(OR(AO16<0,L16="FBA海运"),"","渠道") -> 渠道 | D16: =ROUND(IF(AND(AO16>=0,Y16="正常走货"),_xlfn.XLOOKUP(G16,过机服务商重量差!A:A,过机服务商重量差!L:L),"0"),2) -> 37 | E16: =ROUND(IF(B16="小旋风",$D16/提成!$D$4*提成!$E$4,$D16/提成!$D$3*提成!$E$3),2) -> 0.37 | F16: =IFERROR(LOOKUP(1,0/((B16=名单!B:B)*(VALUE(AW16)>=名单!E:E)*(VALUE(AW16)<=名单!G:G)*(Y16="正常走货")),名单!H:H),"否") -> 是 | G16: SP260121188 | H16: KP | J16: 加拿大海派-JY | L16: 非主营 | S16: 马淞浦 | T16: 营销一部 | Y16: 正常走货 | AO16: 29.9 | AW16: 2026-01-31 22:24:58
A17: =MID(AW17,1,7) -> 2026-01 | B17: =_xlfn.XLOOKUP(G17,过机服务商重量差!A:A,过机服务商重量差!G:G) -> 风清扬 | C17: =IF(OR(AO17<0,L17="FBA海运"),"","渠道") -> 渠道 | D17: =ROUND(IF(AND(AO17>=0,Y17="正常走货"),_xlfn.XLOOKUP(G17,过机服务商重量差!A:A,过机服务商重量差!L:L),"0"),2) -> 26 | E17: =ROUND(IF(B17="小旋风",$D17/提成!$D$4*提成!$E$4,$D17/提成!$D$3*提成!$E$3),2) -> 0.26 | F17: =IFERROR(LOOKUP(1,0/((B17=名单!B:B)*(VALUE(AW17)>=名单!E:E)*(VALUE(AW17)<=名单!G:G)*(Y17="正常走货")),名单!H:H),"否") -> 是 | G17: SP260121174 | H17: KP | J17: 加拿大海派-JY | L17: 非主营 | S17: 马淞浦 | T17: 营销一部 | Y17: 正常走货 | AO17: 173.4 | AW17: 2026-01-31 22:24:21
A18: =MID(AW18,1,7) -> 2026-01 | B18: =_xlfn.XLOOKUP(G18,过机服务商重量差!A:A,过机服务商重量差!G:G) -> 张诚 | C18: =IF(OR(AO18<0,L18="FBA海运"),"","渠道") -> 渠道 | D18: =ROUND(IF(AND(AO18>=0,Y18="正常走货"),_xlfn.XLOOKUP(G18,过机服务商重量差!A:A,过机服务商重量差!L:L),"0"),2) -> 41 | E18: =ROUND(IF(B18="小旋风",$D18/提成!$D$4*提成!$E$4,$D18/提成!$D$3*提成!$E$3),2) -> 0.41 | F18: =IFERROR(LOOKUP(1,0/((B18=名单!B:B)*(VALUE(AW18)>=名单!E:E)*(VALUE(AW18)<=名单!G:G)*(Y18="正常走货")),名单!H:H),"否") -> 否 | G18: SP260121195 | J18: 欧洲海卡包税-MM | L18: 非主营 | S18: 马淞浦 | T18: 营销一部 | Y18: 正常走货 | AO18: 594 | AW18: 2026-01-31 22:24:04
A19: =MID(AW19,1,7) -> 2026-01 | B19: =_xlfn.XLOOKUP(G19,过机服务商重量差!A:A,过机服务商重量差!G:G) -> 张诚 | C19: =IF(OR(AO19<0,L19="FBA海运"),"","渠道") -> 渠道 | D19: =ROUND(IF(AND(AO19>=0,Y19="正常走货"),_xlfn.XLOOKUP(G19,过机服务商重量差!A:A,过机服务商重量差!L:L),"0"),2) -> 313 | E19: =ROUND(IF(B19="小旋风",$D19/提成!$D$4*提成!$E$4,$D19/提成!$D$3*提成!$E$3),2) -> 3.13 | F19: =IFERROR(LOOKUP(1,0/((B19=名单!B:B)*(VALUE(AW19)>=名单!E:E)*(VALUE(AW19)<=名单!G:G)*(Y19="正常走货")),名单!H:H),"否") -> 否 | G19: SP260121223 | J19: 欧洲海卡包税-MM | L19: 非主营 | S19: 马淞浦 | T19: 营销一部 | Y19: 正常走货 | AO19: 4225.5 | AW19: 2026-01-31 22:20:47
A20: =MID(AW20,1,7) -> 2026-01 | B20: =_xlfn.XLOOKUP(G20,过机服务商重量差!A:A,过机服务商重量差!G:G) -> 风清扬 | C20: =IF(OR(AO20<0,L20="FBA海运"),"","渠道") | D20: =ROUND(IF(AND(AO20>=0,Y20="正常走货"),_xlfn.XLOOKUP(G20,过机服务商重量差!A:A,过机服务商重量差!L:L),"0"),2) -> 0 | E20: =ROUND(IF(B20="小旋风",$D20/提成!$D$4*提成!$E$4,$D20/提成!$D$3*提成!$E$3),2) -> 0 | F20: =IFERROR(LOOKUP(1,0/((B20=名单!B:B)*(VALUE(AW20)>=名单!E:E)*(VALUE(AW20)<=名单!G:G)*(Y20="正常走货")),名单!H:H),"否") -> 是 | G20: SP260120043-YYZ7-16 | H20: KP | J20: 加拿大海派-JY | L20: 非主营 | S20: 马淞浦 | T20: 营销一部 | Y20: 正常走货 | AO20: -1287.4 | AW20: 2026-01-31 22:18:11
A21: =MID(AW21,1,7) -> 2026-01 | B21: =_xlfn.XLOOKUP(G21,过机服务商重量差!A:A,过机服务商重量差!G:G) -> 风清扬 | C21: =IF(OR(AO21<0,L21="FBA海运"),"","渠道") | D21: =ROUND(IF(AND(AO21>=0,Y21="正常走货"),_xlfn.XLOOKUP(G21,过机服务商重量差!A:A,过机服务商重量差!L:L),"0"),2) -> 0 | E21: =ROUND(IF(B21="小旋风",$D21/提成!$D$4*提成!$E$4,$D21/提成!$D$3*提成!$E$3),2) -> 0 | F21: =IFERROR(LOOKUP(1,0/((B21=名单!B:B)*(VALUE(AW21)>=名单!E:E)*(VALUE(AW21)<=名单!G:G)*(Y21="正常走货")),名单!H:H),"否") -> 是 | G21: SP260126064-YYZ7-38 | H21: KP | J21: 加拿大海派-JY | L21: 非主营 | S21: 马淞浦 | T21: 营销一部 | Y21: 正常走货 | AO21: -2935.6 | AW21: 2026-01-31 22:17:08
A22: =MID(AW22,1,7) -> 2026-01 | B22: =_xlfn.XLOOKUP(G22,过机服务商重量差!A:A,过机服务商重量差!G:G) -> 张诚 | C22: =IF(OR(AO22<0,L22="FBA海运"),"","渠道") -> 渠道 | D22: =ROUND(IF(AND(AO22>=0,Y22="正常走货"),_xlfn.XLOOKUP(G22,过机服务商重量差!A:A,过机服务商重量差!L:L),"0"),2) -> 634 | E22: =ROUND(IF(B22="小旋风",$D22/提成!$D$4*提成!$E$4,$D22/提成!$D$3*提成!$E$3),2) -> 6.34 | F22: =IFERROR(LOOKUP(1,0/((B22=名单!B:B)*(VALUE(AW22)>=名单!E:E)*(VALUE(AW22)<=名单!G:G)*(Y22="正常走货")),名单!H:H),"否") -> 否 | G22: SP260112003 | J22: 欧洲海卡包税-MM | L22: 非主营 | S22: 马淞浦 | T22: 营销一部 | Y22: 正常走货 | AO22: 7975.8 | AW22: 2026-01-31 22:12:25
A23: =MID(AW23,1,7) -> 2026-01 | B23: =_xlfn.XLOOKUP(G23,过机服务商重量差!A:A,过机服务商重量差!G:G) -> 小旋风 | C23: =IF(OR(AO23<0,L23="FBA海运"),"","渠道") -> 渠道 | D23: =ROUND(IF(AND(AO23>=0,Y23="正常走货"),_xlfn.XLOOKUP(G23,过机服务商重量差!A:A,过机服务商重量差!L:L),"0"),2) -> 37 | E23: =ROUND(IF(B23="小旋风",$D23/提成!$D$4*提成!$E$4,$D23/提成!$D$3*提成!$E$3),2) -> 0.37 | F23: =IFERROR(LOOKUP(1,0/((B23=名单!B:B)*(VALUE(AW23)>=名单!E:E)*(VALUE(AW23)<=名单!G:G)*(Y23="正常走货")),名单!H:H),"否") -> 是 | G23: HCLSA0131-6 | H23: TPL000134937 | J23: 澳大利亚海派-含税-SC | L23: 非主营 | S23: 刘申奥 | T23: 营销五部 | Y23: 正常走货 | AO23: 195.9 | AW23: 2026-01-31 22:08:59
A24: =MID(AW24,1,7) -> 2026-01 | B24: =_xlfn.XLOOKUP(G24,过机服务商重量差!A:A,过机服务商重量差!G:G) -> 张诚 | C24: =IF(OR(AO24<0,L24="FBA海运"),"","渠道") -> 渠道 | D24: =ROUND(IF(AND(AO24>=0,Y24="正常走货"),_xlfn.XLOOKUP(G24,过机服务商重量差!A:A,过机服务商重量差!L:L),"0"),2) -> 503 | E24: =ROUND(IF(B24="小旋风",$D24/提成!$D$4*提成!$E$4,$D24/提成!$D$3*提成!$E$3),2) -> 5.03 | F24: =IFERROR(LOOKUP(1,0/((B24=名单!B:B)*(VALUE(AW24)>=名单!E:E)*(VALUE(AW24)<=名单!G:G)*(Y24="正常走货")),名单!H:H),"否") -> 否 | G24: SP260121154 | J24: 欧洲海卡包税-MM | L24: 非主营 | S24: 马淞浦 | T24: 营销一部 | Y24: 正常走货 | AO24: 6287.5 | AW24: 2026-01-31 22:01:04
A25: =MID(AW25,1,7) -> 2026-01 | B25: =_xlfn.XLOOKUP(G25,过机服务商重量差!A:A,过机服务商重量差!G:G) -> 小旋风 | C25: =IF(OR(AO25<0,L25="FBA海运"),"","渠道") -> 渠道 | D25: =ROUND(IF(AND(AO25>=0,Y25="正常走货"),_xlfn.XLOOKUP(G25,过机服务商重量差!A:A,过机服务商重量差!L:L),"0"),2) -> 52 | E25: =ROUND(IF(B25="小旋风",$D25/提成!$D$4*提成!$E$4,$D25/提成!$D$3*提成!$E$3),2) -> 0.52 | F25: =IFERROR(LOOKUP(1,0/((B25=名单!B:B)*(VALUE(AW25)>=名单!E:E)*(VALUE(AW25)<=名单!G:G)*(Y25="正常走货")),名单!H:H),"否") -> 是 | G25: YKZXX013102 | H25: 1ZA06B016832064447 | J25: 欧洲德国清专线 | L25: 非主营 | S25: 张小雪 | T25: 营销五部 | Y25: 正常走货 | AO25: 2794 | AW25: 2026-01-31 21:13:41
A26: =MID(AW26,1,7) -> 2026-01 | B26: =_xlfn.XLOOKUP(G26,过机服务商重量差!A:A,过机服务商重量差!G:G) -> 玉麒麟 | C26: =IF(OR(AO26<0,L26="FBA海运"),"","渠道") -> 渠道 | D26: =ROUND(IF(AND(AO26>=0,Y26="正常走货"),_xlfn.XLOOKUP(G26,过机服务商重量差!A:A,过机服务商重量差!L:L),"0"),2) -> 1 | E26: =ROUND(IF(B26="小旋风",$D26/提成!$D$4*提成!$E$4,$D26/提成!$D$3*提成!$E$3),2) -> 0.01 | F26: =IFERROR(LOOKUP(1,0/((B26=名单!B:B)*(VALUE(AW26)>=名单!E:E)*(VALUE(AW26)<=名单!G:G)*(Y26="正常走货")),名单!H:H),"否") -> 否 | G26: TM260131-1CA3 | H26: 888386607575 | J26: OK-FDX-DHL-TNT | L26: 非主营 | S26: 邓健群 | T26: 营销三部 | Y26: 正常走货 | AO26: 17.92 | AW26: 2026-01-31 21:02:14
A27: =MID(AW27,1,7) -> 2026-01 | B27: =_xlfn.XLOOKUP(G27,过机服务商重量差!A:A,过机服务商重量差!G:G) -> 小旋风 | C27: =IF(OR(AO27<0,L27="FBA海运"),"","渠道") -> 渠道 | D27: =ROUND(IF(AND(AO27>=0,Y27="正常走货"),_xlfn.XLOOKUP(G27,过机服务商重量差!A:A,过机服务商重量差!L:L),"0"),2) -> 30 | E27: =ROUND(IF(B27="小旋风",$D27/提成!$D$4*提成!$E$4,$D27/提成!$D$3*提成!$E$3),2) -> 0.3 | F27: =IFERROR(LOOKUP(1,0/((B27=名单!B:B)*(VALUE(AW27)>=名单!E:E)*(VALUE(AW27)<=名单!G:G)*(Y27="正常走货")),名单!H:H),"否") -> 是 | G27: TM260131-2FR2 | H27: 1ZA06B016818572639 | J27: 欧洲德国清专线 | L27: 非主营 | S27: 邓健群 | T27: 营销三部 | Y27: 正常走货 | AO27: 1500 | AW27: 2026-01-31 21:00:55
A28: =MID(AW28,1,7) -> 2026-01 | B28: =_xlfn.XLOOKUP(G28,过机服务商重量差!A:A,过机服务商重量差!G:G) -> 帅时莹 | C28: =IF(OR(AO28<0,L28="FBA海运"),"","渠道") -> 渠道 | D28: =ROUND(IF(AND(AO28>=0,Y28="正常走货"),_xlfn.XLOOKUP(G28,过机服务商重量差!A:A,过机服务商重量差!L:L),"0"),2) -> 208 | E28: =ROUND(IF(B28="小旋风",$D28/提成!$D$4*提成!$E$4,$D28/提成!$D$3*提成!$E$3),2) -> 2.08 | F28: {=IFERROR(LOOKUP(1,0/((B28=名单!B:B)*(VALUE(AW28)>=名单!E:E)*(VALUE(AW28)<=名单!G:G)*(Y28="正常走货")),名单!H:H),"否")} -> 否 | G28: HH233M26 | H28: 1ZF4K3596816247057 | J28: 欧洲专线-HMC | L28: 非主营 | S28: 李娟-业务 | T28: 营销四部 | Y28: 正常走货 | AO28: 2700 | AW28: 2026-01-31 20:59:02
A29: =MID(AW29,1,7) -> 2026-01 | B29: =_xlfn.XLOOKUP(G29,过机服务商重量差!A:A,过机服务商重量差!G:G) -> 玉麒麟 | C29: =IF(OR(AO29<0,L29="FBA海运"),"","渠道") -> 渠道 | D29: =ROUND(IF(AND(AO29>=0,Y29="正常走货"),_xlfn.XLOOKUP(G29,过机服务商重量差!A:A,过机服务商重量差!L:L),"0"),2) -> 10 | E29: =ROUND(IF(B29="小旋风",$D29/提成!$D$4*提成!$E$4,$D29/提成!$D$3*提成!$E$3),2) -> 0.1 | F29: =IFERROR(LOOKUP(1,0/((B29=名单!B:B)*(VALUE(AW29)>=名单!E:E)*(VALUE(AW29)<=名单!G:G)*(Y29="正常走货")),名单!H:H),"否") -> 否 | G29: RSC3104 | H29: 1Z0E465J0413832648 | J29: OK-FDX-DHL-TNT | L29: 非主营 | S29: 汪祺 | T29: 营销二部 | Y29: 正常走货 | AO29: 101.6 | AW29: 2026-01-31 20:56:27
A30: =MID(AW30,1,7) -> 2026-01 | B30: =_xlfn.XLOOKUP(G30,过机服务商重量差!A:A,过机服务商重量差!G:G) -> 玉麒麟 | C30: =IF(OR(AO30<0,L30="FBA海运"),"","渠道") -> 渠道 | D30: =ROUND(IF(AND(AO30>=0,Y30="正常走货"),_xlfn.XLOOKUP(G30,过机服务商重量差!A:A,过机服务商重量差!L:L),"0"),2) -> 10 | E30: =ROUND(IF(B30="小旋风",$D30/提成!$D$4*提成!$E$4,$D30/提成!$D$3*提成!$E$3),2) -> 0.1 | F30: =IFERROR(LOOKUP(1,0/((B30=名单!B:B)*(VALUE(AW30)>=名单!E:E)*(VALUE(AW30)<=名单!G:G)*(Y30="正常走货")),名单!H:H),"否") -> 否 | G30: RSC3103 | H30: 1Z0E465J0419105235 | J30: OK-FDX-DHL-TNT | L30: 非主营 | S30: 汪祺 | T30: 营销二部 | Y30: 正常走货 | AO30: 101.6 | AW30: 2026-01-31 20:56:22
A31: =MID(AW31,1,7) -> 2026-01 | B31: =_xlfn.XLOOKUP(G31,过机服务商重量差!A:A,过机服务商重量差!G:G) -> 玉麒麟 | C31: =IF(OR(AO31<0,L31="FBA海运"),"","渠道") -> 渠道 | D31: =ROUND(IF(AND(AO31>=0,Y31="正常走货"),_xlfn.XLOOKUP(G31,过机服务商重量差!A:A,过机服务商重量差!L:L),"0"),2) -> 5.5 | E31: =ROUND(IF(B31="小旋风",$D31/提成!$D$4*提成!$E$4,$D31/提成!$D$3*提成!$E$3),2) -> 0.06 | F31: =IFERROR(LOOKUP(1,0/((B31=名单!B:B)*(VALUE(AW31)>=名单!E:E)*(VALUE(AW31)<=名单!G:G)*(Y31="正常走货")),名单!H:H),"否") -> 否 | G31: RSC3102 | H31: 1Z0E465J0419058000 | J31: OK-FDX-DHL-TNT | L31: 非主营 | S31: 汪祺 | T31: 营销二部 | Y31: 正常走货 | AO31: 101.6 | AW31: 2026-01-31 20:56:04
A32: =MID(AW32,1,7) -> 2026-01 | B32: =_xlfn.XLOOKUP(G32,过机服务商重量差!A:A,过机服务商重量差!G:G) -> 玉麒麟 | C32: =IF(OR(AO32<0,L32="FBA海运"),"","渠道") -> 渠道 | D32: =ROUND(IF(AND(AO32>=0,Y32="正常走货"),_xlfn.XLOOKUP(G32,过机服务商重量差!A:A,过机服务商重量差!L:L),"0"),2) -> 6.5 | E32: =ROUND(IF(B32="小旋风",$D32/提成!$D$4*提成!$E$4,$D32/提成!$D$3*提成!$E$3),2) -> 0.07 | F32: =IFERROR(LOOKUP(1,0/((B32=名单!B:B)*(VALUE(AW32)>=名单!E:E)*(VALUE(AW32)<=名单!G:G)*(Y32="正常走货")),名单!H:H),"否") -> 否 | G32: RSC3101 | H32: 1Z0E465J0415072448 | J32: OK-FDX-DHL-TNT | L32: 非主营 | S32: 汪祺 | T32: 营销二部 | Y32: 正常走货 | AO32: 101.6 | AW32: 2026-01-31 20:55:58
A33: =MID(AW33,1,7) -> 2026-01 | B33: =_xlfn.XLOOKUP(G33,过机服务商重量差!A:A,过机服务商重量差!G:G) -> 玉麒麟 | C33: =IF(OR(AO33<0,L33="FBA海运"),"","渠道") -> 渠道 | D33: =ROUND(IF(AND(AO33>=0,Y33="正常走货"),_xlfn.XLOOKUP(G33,过机服务商重量差!A:A,过机服务商重量差!L:L),"0"),2) -> 52 | E33: =ROUND(IF(B33="小旋风",$D33/提成!$D$4*提成!$E$4,$D33/提成!$D$3*提成!$E$3),2) -> 0.52 | F33: =IFERROR(LOOKUP(1,0/((B33=名单!B:B)*(VALUE(AW33)>=名单!E:E)*(VALUE(AW33)<=名单!G:G)*(Y33="正常走货")),名单!H:H),"否") -> 否 | G33: QLWJ1781704 | H33: 1Z0E793D0422717448 | J33: OK-UPS红单 | L33: 非主营 | S33: 宁春阳 | T33: 营销二部 | Y33: 正常走货 | AO33: 421.1 | AW33: 2026-01-31 20:53:03
A34: =MID(AW34,1,7) -> 2026-01 | B34: =_xlfn.XLOOKUP(G34,过机服务商重量差!A:A,过机服务商重量差!G:G) -> 玉麒麟 | C34: =IF(OR(AO34<0,L34="FBA海运"),"","渠道") -> 渠道 | D34: =ROUND(IF(AND(AO34>=0,Y34="正常走货"),_xlfn.XLOOKUP(G34,过机服务商重量差!A:A,过机服务商重量差!L:L),"0"),2) -> 29 | E34: =ROUND(IF(B34="小旋风",$D34/提成!$D$4*提成!$E$4,$D34/提成!$D$3*提成!$E$3),2) -> 0.29 | F34: =IFERROR(LOOKUP(1,0/((B34=名单!B:B)*(VALUE(AW34)>=名单!E:E)*(VALUE(AW34)<=名单!G:G)*(Y34="正常走货")),名单!H:H),"否") -> 否 | G34: JHZW7312 | H34: 888384610822 | J34: OK-FDX-DHL-TNT | L34: 非主营 | S34: 宋海周 | T34: 营销二部 | Y34: 正常走货 | AO34: 101.64 | AW34: 2026-01-31 20:46:55
A35: =MID(AW35,1,7) -> 2026-01 | B35: =_xlfn.XLOOKUP(G35,过机服务商重量差!A:A,过机服务商重量差!G:G) -> 风清扬 | C35: =IF(OR(AO35<0,L35="FBA海运"),"","渠道") -> 渠道 | D35: =ROUND(IF(AND(AO35>=0,Y35="正常走货"),_xlfn.XLOOKUP(G35,过机服务商重量差!A:A,过机服务商重量差!L:L),"0"),2) -> 27 | E35: =ROUND(IF(B35="小旋风",$D35/提成!$D$4*提成!$E$4,$D35/提成!$D$3*提成!$E$3),2) -> 0.27 | F35: =IFERROR(LOOKUP(1,0/((B35=名单!B:B)*(VALUE(AW35)>=名单!E:E)*(VALUE(AW35)<=名单!G:G)*(Y35="正常走货")),名单!H:H),"否") -> 是 | G35: SH0131-2 | H35: 1ZHF38642014756797 | J35: 加拿大准时达海派UPS | L35: 非主营 | S35: 小飞侠 | T35: 营销五部 | Y35: 正常走货 | AO35: 377 | AW35: 2026-01-31 20:43:24
A36: =MID(AW36,1,7) -> 2026-01 | B36: =_xlfn.XLOOKUP(G36,过机服务商重量差!A:A,过机服务商重量差!G:G) -> 无崖子 | C36: =IF(OR(AO36<0,L36="FBA海运"),"","渠道") -> 渠道 | D36: =ROUND(IF(AND(AO36>=0,Y36="正常走货"),_xlfn.XLOOKUP(G36,过机服务商重量差!A:A,过机服务商重量差!L:L),"0"),2) -> 7.5 | E36: =ROUND(IF(B36="小旋风",$D36/提成!$D$4*提成!$E$4,$D36/提成!$D$3*提成!$E$3),2) -> 0.08 | F36: =IFERROR(LOOKUP(1,0/((B36=名单!B:B)*(VALUE(AW36)>=名单!E:E)*(VALUE(AW36)<=名单!G:G)*(Y36="正常走货")),名单!H:H),"否") -> 否 | G36: JPS20260131002 | H36: CR431657742DE | J36: HST-UPS 6000 | L36: 非主营 | S36: 柴燕玲 | T36: 四部KA客服 | Y36: 正常走货 | AO36: 225 | AW36: 2026-01-31 20:41:12
A37: =MID(AW37,1,7) -> 2026-01 | B37: =_xlfn.XLOOKUP(G37,过机服务商重量差!A:A,过机服务商重量差!G:G) -> 无崖子 | C37: =IF(OR(AO37<0,L37="FBA海运"),"","渠道") -> 渠道 | D37: =ROUND(IF(AND(AO37>=0,Y37="正常走货"),_xlfn.XLOOKUP(G37,过机服务商重量差!A:A,过机服务商重量差!L:L),"0"),2) -> 6 | E37: =ROUND(IF(B37="小旋风",$D37/提成!$D$4*提成!$E$4,$D37/提成!$D$3*提成!$E$3),2) -> 0.06 | F37: =IFERROR(LOOKUP(1,0/((B37=名单!B:B)*(VALUE(AW37)>=名单!E:E)*(VALUE(AW37)<=名单!G:G)*(Y37="正常走货")),名单!H:H),"否") -> 否 | G37: JPS20260131001 | H37: CR431657314DE | J37: HST-UPS 6000 | L37: 非主营 | S37: 柴燕玲 | T37: 四部KA客服 | Y37: 正常走货 | AO37: 229.36 | AW37: 2026-01-31 20:41:04
A38: =MID(AW38,1,7) -> 2026-01 | B38: =_xlfn.XLOOKUP(G38,过机服务商重量差!A:A,过机服务商重量差!G:G) -> 玉麒麟 | C38: =IF(OR(AO38<0,L38="FBA海运"),"","渠道") -> 渠道 | D38: =ROUND(IF(AND(AO38>=0,Y38="正常走货"),_xlfn.XLOOKUP(G38,过机服务商重量差!A:A,过机服务商重量差!L:L),"0"),2) -> 25 | E38: =ROUND(IF(B38="小旋风",$D38/提成!$D$4*提成!$E$4,$D38/提成!$D$3*提成!$E$3),2) -> 0.25 | F38: =IFERROR(LOOKUP(1,0/((B38=名单!B:B)*(VALUE(AW38)>=名单!E:E)*(VALUE(AW38)<=名单!G:G)*(Y38="正常走货")),名单!H:H),"否") -> 否 | G38: PBI3-FBA19757N66N | H38: 1Z0E465J0407453337 | J38: OK-FDX-DHL-TNT | L38: 非主营 | S38: 李娟-业务 | T38: 营销四部 | Y38: 正常走货 | AO38: 329.1 | AW38: 2026-01-31 20:40:50
A39: =MID(AW39,1,7) -> 2026-01 | B39: =_xlfn.XLOOKUP(G39,过机服务商重量差!A:A,过机服务商重量差!G:G) -> 帅时莹 | C39: =IF(OR(AO39<0,L39="FBA海运"),"","渠道") -> 渠道 | D39: =ROUND(IF(AND(AO39>=0,Y39="正常走货"),_xlfn.XLOOKUP(G39,过机服务商重量差!A:A,过机服务商重量差!L:L),"0"),2) -> 3.5 | E39: =ROUND(IF(B39="小旋风",$D39/提成!$D$4*提成!$E$4,$D39/提成!$D$3*提成!$E$3),2) -> 0.04 | F39: =IFERROR(LOOKUP(1,0/((B39=名单!B:B)*(VALUE(AW39)>=名单!E:E)*(VALUE(AW39)<=名单!G:G)*(Y39="正常走货")),名单!H:H),"否") -> 否 | G39: 95T6963 | H39: 1ZG3333D0406480200 | J39: MSHQ-UPS | L39: 非主营 | S39: 李娟-业务 | T39: 营销四部 | Y39: 正常走货 | AO39: 139.1 | AW39: 2026-01-31 20:40:36
A40: =MID(AW40,1,7) -> 2026-01 | B40: =_xlfn.XLOOKUP(G40,过机服务商重量差!A:A,过机服务商重量差!G:G) -> 风清扬 | C40: =IF(OR(AO40<0,L40="FBA海运"),"","渠道") -> 渠道 | D40: =ROUND(IF(AND(AO40>=0,Y40="正常走货"),_xlfn.XLOOKUP(G40,过机服务商重量差!A:A,过机服务商重量差!L:L),"0"),2) -> 142 | E40: =ROUND(IF(B40="小旋风",$D40/提成!$D$4*提成!$E$4,$D40/提成!$D$3*提成!$E$3),2) -> 1.42 | F40: =IFERROR(LOOKUP(1,0/((B40=名单!B:B)*(VALUE(AW40)>=名单!E:E)*(VALUE(AW40)<=名单!G:G)*(Y40="正常走货")),名单!H:H),"否") -> 是 | G40: 24543733501033648 | H40: 881072500 | J40: 东南亚专线 | L40: 非主营 | S40: 丁佳伟 | T40: 营销三部 | Y40: 正常走货 | AO40: 1361 | AW40: 2026-01-31 20:40:27
...

Sheet 名单
B1: 客服系统名 | C1: 姓名 | D1: 入职时间 | E1: 提成计算开始日期 | F1: 结束日期（手填） | G1: 结束日期 | H1: 是否计算提成
B2: 无崖子 | C2: 陈巧玲 | E2: 45078 | F2: 45716 | G2: =IF(F2="",TODAY(),F2) -> 45716 | H2: 否
B3: 霹雳火-快递客服(杨帆) | C3: 杨帆 | E3: 45123 | F3: 45276 | G3: =IF(F3="",TODAY(),F3) -> 45276 | H3: 否
B4: 风清扬 | C4: 陈晓密 | E4: 45748 | G4: =IF(F4="",TODAY(),F4) -> 46091 | H4: 是
B5: 小旋风 | C5: 吴敏洁 | E5: 45748 | G5: =IF(F5="",TODAY(),F5) -> 46091 | H5: 是

Sheet 提成标准
N2: 渠道 | O2: 中转状态 | Q2: 大于等于 | R2: 小于 | S2: 取数 | T2: 单位 | U2: 提成系数（元） | V2: 截止到2023.12.14（其中杨帆的是到离职日16日）
B3: 中转状态 | F3: 取数 | G3: 单位 | H3: 提成系数（元） | I3: 2025.4.1开始 | N3: 快递 | O3: 正常走货 | P3: 快递小货 | Q3: 0 | R3: 21 | S3: 1 | T3: 票 | U3: 2 | V3: 2元/票
B4: 正常走货 | D4: 0 | E4: 100000 | F4: 出货计费重 | G4: KG | H4: 0.01 | I4: 0.01元/KG | N4: 快递 | O4: 正常走货 | P4: 快递大货 | Q4: 21 | R4: 99999 | S4: 出货计费重 | T4: KG | U4: 0.2 | V4: 0.2元/KG
B5: 正常走货 | D5: 100000 | E5: 150000 | F5: 出货计费重 | G5: KG | H5: 0.015 | I5: 0.015元/KG | N5: 专线 | O5: 正常走货 | P5: 专线 | S5: 出货计费重 | T5: KG | U5: 0.1 | V5: 0.1元/KG
B6: 正常走货 | D6: 150000 | E6: 200000 | F6: 出货计费重 | G6: KG | H6: 0.02 | I6: 0.02元/KG | N6: 主营产品 | P6: 主营产品 | U6: 0
B7: 正常走货 | D7: 200000 | E7: 300000 | F7: 出货计费重 | G7: KG | H7: 0.025 | I7: 0.025元/KG
B8: 正常走货 | D8: 300000 | E8: 999999999 | F8: 出货计费重 | G8: KG | H8: 0.035 | I8: 0.035元/KG | N8: 渠道 | O8: 中转状态 | Q8: 大于等于 | R8: 小于 | S8: 取数 | T8: 单位 | U8: 提成系数（元） | V8: 2023.12.15开始
A9: 阶段性的，例如：3月负责线路收货吨数133吨，则提成计算公式为 | N9: 快递 | O9: 正常走货 | P9: 快递小货 | Q9: 0 | R9: 21 | S9: 1 | T9: 票 | U9: 2 | V9: 2元/票
B10: 100000*0.01)+(133000-100000)*0.015=1495元 | N10: 快递 | O10: 正常走货 | P10: 快递大货 | Q10: 21 | R10: 99999 | S10: 出货计费重 | T10: KG | U10: 0.1 | V10: 0.1元/KG
N11: 专线 | O11: 正常走货 | P11: 专线 | S11: 出货计费重 | T11: KG | U11: 0.1 | V11: 0.1元/KG
C12: 出货计费重KG | D12: 提成系数（元） | N12: 主营产品 | P12: 主营产品 | U12: 0
C13: 0 | D13: 0.01 | E13: 0
C14: 100000 | D14: 0.015 | E14: =C14*(D14-D13) -> 500
C15: 150000 | D15: 0.02 | E15: =E14+C15*(D15-D14) -> 1250
C16: 200000 | D16: 0.025 | E16: =E15+C16*(D16-D15) -> 2250
C17: 300000 | D17: 0.035 | E17: =E16+C17*(D17-D16) -> 5250

Sheet 特殊事项扣除
A1: 扣除期间 | B1: 客服名 | C1: 扣除金额 | D1: 单号期间 | E1: 备注 | F1: 单号
A2: 2023-07 | B2: 霹雳火-快递客服(杨帆) | C2: 724.12 | D2: 45110 | F2: TJ01532 | G2: =_xlfn.DISPIMG("ID_9F528AFC3D734C0F93B5BDB826E0677E",1) -> =DISPIMG("ID_9F528AFC3D734C0F93B5BDB826E0677E",1)
A3: 2023-08 | B3: 霹雳火-快递客服(杨帆) | C3: 0.7
A4: 2023-08 | B4: 霹雳火-快递客服(杨帆) | C4: 0.7
A5: 2023-08 | B5: 霹雳火-快递客服(杨帆) | C5: 0.71
A6: 2023-08 | B6: 霹雳火-快递客服(杨帆) | C6: 8.27
A7: 2023-08 | B7: 霹雳火-快递客服(杨帆) | C7: 14.68
A8: 2023-08 | B8: 霹雳火-快递客服(杨帆) | C8: 0.01
A9: 2023-08 | B9: 霹雳火-快递客服(杨帆) | C9: 10.69
A10: 2023-08 | B10: 霹雳火-快递客服(杨帆) | C10: 10.69
A11: 2023-08 | B11: 霹雳火-快递客服(杨帆) | C11: 13.35
A12: 2023-08 | B12: 霹雳火-快递客服(杨帆) | C12: 0.01
A13: 2023-08 | B13: 霹雳火-快递客服(杨帆) | C13: 12.69
A14: 2023-08 | B14: 霹雳火-快递客服(杨帆) | C14: 11.35
... A79: 2023-08 | B79: 霹雳火-快递客服(杨帆) | C79: 17.43

Sheet 提成
A1: 渠道客服提成明细表 | H1: 不含渠道毛利负的
A2: 客服系统名 | B2: 姓名 | C2: 期间 | D2: 渠道 正常走货 出货计费重/KG | E2: 应发提成 | F2: 特殊事项扣除 | G2: 实发 提成 | H2: 公账 | I2: 私账
A3: 风清扬 | B3: 陈晓密 | C3: =业务员明细!$F$1 -> 2026-01 | D3: =ROUND(SUMIFS(业务数据统计!$D:$D,业务数据统计!$B:$B,$A3,业务数据统计!C:C,"渠道"),2) -> 96422 | E3: {=ROUND(LOOKUP(1,0/(D3>提成标准!$C$13:$C$17),提成标准!$D$13:$D$17)*D3-LOOKUP(1,0/(D3>提成标准!$C$13:$C$17),提成标准!$E$13:$E$17),2)} -> 964.22 | F3: =SUMIFS(特殊事项扣除!C:C,特殊事项扣除!A:A,C3,特殊事项扣除!B:B,A3) -> 0 | G3: =E3-F3 -> 964.22
A4: 小旋风 | B4: 吴敏洁 | C4: =业务员明细!$F$1 -> 2026-01 | D4: =ROUND(SUMIFS(业务数据统计!$D:$D,业务数据统计!$B:$B,$A4,业务数据统计!C:C,"渠道"),2) -> 67429.11 | E4: {=ROUND(LOOKUP(1,0/(D4>提成标准!$C$13:$C$17),提成标准!$D$13:$D$17)*D4-LOOKUP(1,0/(D4>提成标准!$C$13:$C$17),提成标准!$E$13:$E$17),2)} -> 674.29 | F4: =SUMIFS(特殊事项扣除!C:C,特殊事项扣除!A:A,C4,特殊事项扣除!B:B,A4) -> 0 | G4: =E4-F4 -> 674.29
A5: 合计： | D5: =SUM(D3:D4) -> 163851.11 | E5: =SUM(E3:E4) -> 1638.51 | F5: =SUM(F3:F4) -> 0 | G5: =SUM(G3:G4) -> 1638.51
F7: 制表人：

Sheet 业务员明细
A1: 渠道客服提成明细表（业务员承担） | F1: 2026-01
A2: 系统名 | B2: 部门 | C2: 运单期间 | D2: 承担金额 | E2: 部门
A3: 马淞浦 | B3: =_xlfn.XLOOKUP(E3,部门!A:A,部门!B:B) -> 销售一部 | C3: =$F$1 -> 2026-01 | D3: =SUMIFS(业务数据统计!E:E,业务数据统计!S:S,A3,业务数据统计!F:F,"是")+0.2 -> 129.49 | E3: =_xlfn.XLOOKUP(A3,业务数据统计!S:S,业务数据统计!T:T,"") -> 营销一部
A4: 朱杰 | B4: =_xlfn.XLOOKUP(E4,部门!A:A,部门!B:B) -> 销售四部 | C4: =$F$1 -> 2026-01 | D4: =SUMIFS(业务数据统计!E:E,业务数据统计!S:S,A4,业务数据统计!F:F,"是") -> 105.48 | E4: =_xlfn.XLOOKUP(A4,业务数据统计!S:S,业务数据统计!T:T,"") -> 营销四部 | G4: 销售一部 | H4: =SUMIFS(D:D,B:B,G4) -> 267.9
A5: 陈炎 | B5: =_xlfn.XLOOKUP(E5,部门!A:A,部门!B:B) -> 销售二部 | C5: =$F$1 -> 2026-01 | D5: =SUMIFS(业务数据统计!E:E,业务数据统计!S:S,A5,业务数据统计!F:F,"是") -> 90.53 | E5: =_xlfn.XLOOKUP(A5,业务数据统计!S:S,业务数据统计!T:T,"") -> 营销二部 | G5: 销售四部 | H5: =SUMIFS(D:D,B:B,G5) -> 312.11
A6: 王拥 | B6: =_xlfn.XLOOKUP(E6,部门!A:A,部门!B:B) -> 销售二部 | C6: =$F$1 -> 2026-01 | D6: =SUMIFS(业务数据统计!E:E,业务数据统计!S:S,A6,业务数据统计!F:F,"是") -> 66.14 | E6: =_xlfn.XLOOKUP(A6,业务数据统计!S:S,业务数据统计!T:T,"") -> 营销二部 | G6: 销售二部 | H6: =SUMIFS(D:D,B:B,G6) -> 322.22
A7: 邓健群 | B7: =_xlfn.XLOOKUP(E7,部门!A:A,部门!B:B) -> 销售三部 | C7: =$F$1 -> 2026-01 | D7: =SUMIFS(业务数据统计!E:E,业务数据统计!S:S,A7,业务数据统计!F:F,"是") -> 53.6 | E7: =_xlfn.XLOOKUP(A7,业务数据统计!S:S,业务数据统计!T:T,"") -> 营销三部 | G7: 销售三部 | H7: =SUMIFS(D:D,B:B,G7) -> 268.83
A8: 陈兵 | B8: =_xlfn.XLOOKUP(E8,部门!A:A,部门!B:B) -> 销售一部 | C8: =$F$1 -> 2026-01 | D8: =SUMIFS(业务数据统计!E:E,业务数据统计!S:S,A8,业务数据统计!F:F,"是") -> 51.23 | E8: =_xlfn.XLOOKUP(A8,业务数据统计!S:S,业务数据统计!T:T,"") -> 营销一部 | G8: 宁波 | H8: =SUMIFS(D:D,B:B,G8) -> 89.42
A9: 周志宇 | B9: =_xlfn.XLOOKUP(E9,部门!A:A,部门!B:B) -> 宁波 | C9: =$F$1 -> 2026-01 | D9: =SUMIFS(业务数据统计!E:E,业务数据统计!S:S,A9,业务数据统计!F:F,"是") -> 47.54 | E9: =_xlfn.XLOOKUP(A9,业务数据统计!S:S,业务数据统计!T:T,"") -> 宁波销售一部 | G9: 销售五部 | H9: =SUMIFS(D:D,B:B,G9) -> 226.95
A10: 陈巧玲 | B10: =_xlfn.XLOOKUP(E10,部门!A:A,部门!B:B) -> 销售三部 | C10: =$F$1 -> 2026-01 | D10: =SUMIFS(业务数据统计!E:E,业务数据统计!S:S,A10,业务数据统计!F:F,"是") -> 46.21 | E10: =_xlfn.XLOOKUP(A10,业务数据统计!S:S,业务数据统计!T:T,"") -> 营销三部 | G10: 厦门 | H10: =SUMIFS(D:D,B:B,G10) -> 30.43
A11: 李凤 | B11: =_xlfn.XLOOKUP(E11,部门!A:A,部门!B:B) -> 销售四部 | C11: =$F$1 -> 2026-01 | D11: =SUMIFS(业务数据统计!E:E,业务数据统计!S:S,A11,业务数据统计!F:F,"是") -> 45.19 | E11: =_xlfn.XLOOKUP(A11,业务数据统计!S:S,业务数据统计!T:T,"") -> 营销四部 | G11: 台州 | H11: =SUMIFS(D:D,B:B,G11) -> 32.24
A12: 冯青青 | B12: =_xlfn.XLOOKUP(E12,部门!A:A,部门!B:B) -> 销售五部 | C12: =$F$1 -> 2026-01 | D12: =SUMIFS(业务数据统计!E:E,业务数据统计!S:S,A12,业务数据统计!F:F,"是") -> 43.01 | E12: =_xlfn.XLOOKUP(A12,业务数据统计!S:S,业务数据统计!T:T,"") -> 营销五部 | G12: 福永 | H12: =SUMIFS(D:D,B:B,G12) -> 34.27
A13: 付乐航 | B13: =_xlfn.XLOOKUP(E13,部门!A:A,部门!B:B) -> 销售五部 | C13: =$F$1 -> 2026-01 | D13: =SUMIFS(业务数据统计!E:E,业务数据统计!S:S,A13,业务数据统计!F:F,"是") -> 39.19 | E13: =_xlfn.XLOOKUP(A13,业务数据统计!S:S,业务数据统计!T:T,"") -> 营销五部 | G13: 深圳 | H13: =SUMIFS(D:D,B:B,G13) -> 39.27
A14: 丁佳伟 | B14: =_xlfn.XLOOKUP(E14,部门!A:A,部门!B:B) -> 销售三部 | C14: =$F$1 -> 2026-01 | D14: =SUMIFS(业务数据统计!E:E,业务数据统计!S:S,A14,业务数据统计!F:F,"是") -> 37.72 | E14: =_xlfn.XLOOKUP(A14,业务数据统计!S:S,业务数据统计!T:T,"") -> 营销三部 | G14: 潍坊 | H14: =SUMIFS(D:D,B:B,G14) -> 8.57
A15: 李可 | B15: =_xlfn.XLOOKUP(E15,部门!A:A,部门!B:B) -> 销售四部 | C15: =$F$1 -> 2026-01 | D15: =SUMIFS(业务数据统计!E:E,业务数据统计!S:S,A15,业务数据统计!F:F,"是") -> 35.69 | E15: =_xlfn.XLOOKUP(A15,业务数据统计!S:S,业务数据统计!T:T,"") -> 营销四部 | G15: 杭州 | H15: =SUMIFS(D:D,B:B,G15) -> 4.74
A16: 徐建 | B16: =_xlfn.XLOOKUP(E16,部门!A:A,部门!B:B) -> 销售三部 | C16: =$F$1 -> 2026-01 | D16: =SUMIFS(业务数据统计!E:E,业务数据统计!S:S,A16,业务数据统计!F:F,"是") -> 33.98 | E16: =_xlfn.XLOOKUP(A16,业务数据统计!S:S,业务数据统计!T:T,"") -> 营销三部 | G16: 广州 | H16: =SUMIFS(D:D,B:B,G16) -> 1.56
A17: 陈颖 | B17: =_xlfn.XLOOKUP(E17,部门!A:A,部门!B:B) -> 销售五部 | C17: =$F$1 -> 2026-01 | D17: =SUMIFS(业务数据统计!E:E,业务数据统计!S:S,A17,业务数据统计!F:F,"是") -> 30.47 | E17: =_xlfn.XLOOKUP(A17,业务数据统计!S:S,业务数据统计!T:T,"") -> 营销五部
A18: 俞平 | B18: =_xlfn.XLOOKUP(E18,部门!A:A,部门!B:B) -> 厦门 | C18: =$F$1 -> 2026-01 | D18: =SUMIFS(业务数据统计!E:E,业务数据统计!S:S,A18,业务数据统计!F:F,"是") -> 30.43 | E18: =_xlfn.XLOOKUP(A18,业务数据统计!S:S,业务数据统计!T:T,"") -> 厦门销售一部
A19: 张俊合 | B19: =_xlfn.XLOOKUP(E19,部门!A:A,部门!B:B) -> 销售五部 | C19: =$F$1 -> 2026-01 | D19: =SUMIFS(业务数据统计!E:E,业务数据统计!S:S,A19,业务数据统计!F:F,"是") -> 29.43 | E19: =_xlfn.XLOOKUP(A19,业务数据统计!S:S,业务数据统计!T:T,"") -> 营销五部 | H19: =SUM(H4:H18) -> 1638.51
A20: 鞠敬伟 | B20: =_xlfn.XLOOKUP(E20,部门!A:A,部门!B:B) -> 销售三部 | C20: =$F$1 -> 2026-01 | D20: =SUMIFS(业务数据统计!E:E,业务数据统计!S:S,A20,业务数据统计!F:F,"是") -> 29.15 | E20: =_xlfn.XLOOKUP(A20,业务数据统计!S:S,业务数据统计!T:T,"") -> 营销三部 | H20: =提成!G5 -> 1638.51
A21: 何林霞 | B21: =_xlfn.XLOOKUP(E21,部门!A:A,部门!B:B) -> 销售二部 | C21: =$F$1 -> 2026-01 | D21: =SUMIFS(业务数据统计!E:E,业务数据统计!S:S,A21,业务数据统计!F:F,"是") -> 27.98 | E21: =_xlfn.XLOOKUP(A21,业务数据统计!S:S,业务数据统计!T:T,"") -> 营销二部 | H21: =H19-H20 -> 0
A22: 徐凌志 | B22: =_xlfn.XLOOKUP(E22,部门!A:A,部门!B:B) -> 宁波 | C22: =$F$1 -> 2026-01 | D22: =SUMIFS(业务数据统计!E:E,业务数据统计!S:S,A22,业务数据统计!F:F,"是") -> 27.67 | E22: =_xlfn.XLOOKUP(A22,业务数据统计!S:S,业务数据统计!T:T,"") -> 宁波销售一部
A23: 陈燚 | B23: =_xlfn.XLOOKUP(E23,部门!A:A,部门!B:B) -> 台州 | C23: =$F$1 -> 2026-01 | D23: =SUMIFS(业务数据统计!E:E,业务数据统计!S:S,A23,业务数据统计!F:F,"是") -> 26.68 | E23: =_xlfn.XLOOKUP(A23,业务数据统计!S:S,业务数据统计!T:T,"") -> 台州销售一部
A24: 王昌金 | B24: =_xlfn.XLOOKUP(E24,部门!A:A,部门!B:B) -> 销售一部 | C24: =$F$1 -> 2026-01 | D24: =SUMIFS(业务数据统计!E:E,业务数据统计!S:S,A24,业务数据统计!F:F,"是") -> 24.51 | E24: =_xlfn.XLOOKUP(A24,业务数据统计!S:S,业务数据统计!T:T,"") -> 营销一部
A25: 黄小丽 | B25: =_xlfn.XLOOKUP(E25,部门!A:A,部门!B:B) -> 销售四部 | C25: =$F$1 -> 2026-01 | D25: =SUMIFS(业务数据统计!E:E,业务数据统计!S:S,A25,业务数据统计!F:F,"是") -> 24.23 | E25: =_xlfn.XLOOKUP(A25,业务数据统计!S:S,业务数据统计!T:T,"") -> 营销四部
A26: 叶伟明 | B26: =_xlfn.XLOOKUP(E26,部门!A:A,部门!B:B) -> 销售一部 | C26: =$F$1 -> 2026-01 | D26: =SUMIFS(业务数据统计!E:E,业务数据统计!S:S,A26,业务数据统计!F:F,"是") -> 24.01 | E26: =_xlfn.XLOOKUP(A26,业务数据统计!S:S,业务数据统计!T:T,"") -> 营销一部
A27: 刘申奥 | B27: =_xlfn.XLOOKUP(E27,部门!A:A,部门!B:B) -> 销售五部 | C27: =$F$1 -> 2026-01 | D27: =SUMIFS(业务数据统计!E:E,业务数据统计!S:S,A27,业务数据统计!F:F,"是") -> 23.3 | E27: =_xlfn.XLOOKUP(A27,业务数据统计!S:S,业务数据统计!T:T,"") -> 营销五部
A28: 张小雪 | B28: =_xlfn.XLOOKUP(E28,部门!A:A,部门!B:B) -> 销售五部 | C28: =$F$1 -> 2026-01 | D28: =SUMIFS(业务数据统计!E:E,业务数据统计!S:S,A28,业务数据统计!F:F,"是") -> 22.71 | E28: =_xlfn.XLOOKUP(A28,业务数据统计!S:S,业务数据统计!T:T,"") -> 营销五部
A29: 王岩岩 | B29: =_xlfn.XLOOKUP(E29,部门!A:A,部门!B:B) -> 销售四部 | C29: =$F$1 -> 2026-01 | D29: =SUMIFS(业务数据统计!E:E,业务数据统计!S:S,A29,业务数据统计!F:F,"是") -> 21.34 | E29: =_xlfn.XLOOKUP(A29,业务数据统计!S:S,业务数据统计!T:T,"") -> 营销四部
A30: 李杰 | B30: =_xlfn.XLOOKUP(E30,部门!A:A,部门!B:B) -> 福永 | C30: =$F$1 -> 2026-01 | D30: =SUMIFS(业务数据统计!E:E,业务数据统计!S:S,A30,业务数据统计!F:F,"是") -> 20.97 | E30: =_xlfn.XLOOKUP(A30,业务数据统计!S:S,业务数据统计!T:T,"") -> 福永销售九部
A31: 左宗伟 | B31: =_xlfn.XLOOKUP(E31,部门!A:A,部门!B:B) -> 销售四部 | C31: =$F$1 -> 2026-01 | D31: =SUMIFS(业务数据统计!E:E,业务数据统计!S:S,A31,业务数据统计!F:F,"是") -> 20.93 | E31: =_xlfn.XLOOKUP(A31,业务数据统计!S:S,业务数据统计!T:T,"") -> 营销四部
A32: 江伟成 | B32: =_xlfn.XLOOKUP(E32,部门!A:A,部门!B:B) -> 销售二部 | C32: =$F$1 -> 2026-01 | D32: =SUMIFS(业务数据统计!E:E,业务数据统计!S:S,A32,业务数据统计!F:F,"是") -> 19.94 | E32: =_xlfn.XLOOKUP(A32,业务数据统计!S:S,业务数据统计!T:T,"") -> 营销二部
A33: 高雨晴 | B33: =_xlfn.XLOOKUP(E33,部门!A:A,部门!B:B) -> 销售二部 | C33: =$F$1 -> 2026-01 | D33: =SUMIFS(业务数据统计!E:E,业务数据统计!S:S,A33,业务数据统计!F:F,"是") -> 19.47 | E33: =_xlfn.XLOOKUP(A33,业务数据统计!S:S,业务数据统计!T:T,"") -> 营销二部
... A115: 于振康 | B115: =_xlfn.XLOOKUP(E115,部门!A:A,部门!B:B) -> 销售一部 | C115: =$F$1 -> 2026-01 | D115: =SUMIFS(业务数据统计!E:E,业务数据统计!S:S,A115,业务数据统计!F:F,"是") -> 0 | E115: =_xlfn.XLOOKUP(A115,业务数据统计!S:S,业务数据统计!T:T,"") -> 营销一部
A116: 合计： | D116: =SUM(D3:D115) -> 1638.51

Sheet 部门
A1: 业务员部门 | B1: 部门
A2: KA部-亮剑队 | B2: KA部
A3: KA部-一组长 | B3: KA部
A4: KA部-群英队 | B4: KA部
A5: 北苑-业务员 | B5: 北苑
A6: 北苑-业务员-陈伟 | B6: 北苑
A7: 北苑-业务员-冯玉勋 | B7: 北苑
A8: 广州分公司-业务员 | B8: 广州
A9: 广州分公司-业务员(曹深研) | B9: 广州
A10: 广州分公司-业务员(练思强) | B10: 广州
A11: 广州分公司-业务员(周源伟) | B11: 广州
A12: 广州分公司-业务员-马井贝 | B12: 广州
... A22: 深圳-业务员-刘薇 | B22: 深圳
A23: 深圳-直客-业务员 | B23: 深圳 | E23: 、
A24: 深圳-直客-坂田 | B24: 深圳
A25: 拓展部-飓风队 | B25: 拓展部-直客
A26: 吴慧俊
A27: 下王公司-业务员 | B27: 下王
A28: 下王公司-总经理 | B28: 下王
A29: 下王-业务员 | B29: 下王
A30: 销售二部-第一队 | B30: 营销二部
A31: 销售二部-昊阳队 | B31: 营销二部
A32: 销售二部-烈火队 | B32: 营销二部
A33: 销售二部-野狼队 | B33: 营销二部
A34: 销售三部-战狼队 | B34: 销售三部
A35: 销售三部-主管 | B35: 销售三部
A36: 销售一部-火箭队 | B36: 销售一部
A37: 销售一部-迈凯伦队 | B37: 销售一部
A38: 销售一部-王炸队 | B38: 销售一部
... A106: 四部KA客服 | B106: 销售四部
