Workbook

Sheet 过机服务商重量差
A1: 运单号 | B1: 服务商单号 | C1: 渠道转单号 | D1: 销售产品 | E1: 产品组 | F1: 服务渠道 | G1: 服务渠道客服 | H1: 客户简称 | I1: 业务员名称 | J1: 出货实重 | K1: 出货材积重 | L1: 出货计费重 | M1: 服务商计费重 | N1: 差值
A2: QS0131-MX | B2: ICBU00000932919 | C2: 1ZG3325W0416448603 | D2: OK-FDX-DHL-TNT | E2: 非主营 | F2: OK-FDX-DHL-TNT | G2: 玉麒麟 | I2: 小飞侠 | J2: 1.87 | K2: 4.059 | L2: 3.5 | M2: 4.5 | N2: 1
A3: TL0131-NL | B3: ICBU00000932943 | C3: 1Z4W260E0409673969 | D3: OK-UPS红单 | E3: 非主营 | F3: OK-UPS红单 | G3: 玉麒麟 | I3: 小飞侠 | J3: 9.23 | K3: 4.277 | L3: 9.5 | M3: 9.5 | N3: 0
A4: FBA15G65R8GW | B4: ICBU00000932665 | C4: RCD24000759946 | D4: 澳大利亚海派-包税 | E4: 非主营 | F4: 澳大利亚海派-包税 | G4: 小旋风 | I4: 高雨晴 | J4: 105.07 | K4: 0.654 | L4: 0.7 | M4: 0.8 | N4: 0.1
A5: FBA15G65P13K | B5: ICBU00000932701 | C5: RCD24000759947 | D5: 澳大利亚海派-包税 | E5: 非主营 | F5: 澳大利亚海派-包税 | G5: 小旋风 | I5: 高雨晴 | J5: 77.91 | K5: 0.647 | L5: 0.8 | M5: 0.8 | N5: 0
A6: SP260122021 | B6: ICBU00000933108 | D6: 欧洲海派-M | E6: 非主营 | F6: 欧洲海派-M | G6: 张诚 | I6: 马淞浦 | J6: 43.64 | K6: 35.783 | L6: 44 | M6: 44 | N6: 0
A7: SP260129024 | B7: ICBU00000933109 | D7: 欧洲海派-M | E7: 非主营 | F7: 欧洲海派-M | G7: 张诚 | I7: 马淞浦 | J7: 235.02 | K7: 201.12 | L7: 236 | M7: 236 | N7: 0
A8: SP260121227 | B8: ICBU00000933107 | D8: 欧洲海派-M | E8: 非主营 | F8: 欧洲海派-M | G8: 张诚 | I8: 马淞浦 | J8: 76.54 | K8: 55.296 | L8: 77 | M8: 77 | N8: 0
A9: SP260123008 | B9: ICBU00000933118 | D9: 欧洲海派-M | E9: 非主营 | F9: 欧洲海派-M | G9: 张诚 | I9: 马淞浦 | J9: 182.35 | K9: 157.348 | L9: 183 | M9: 183 | N9: 0
A10: SP260122003 | B10: ICBU00000933106 | D10: 欧洲海派-M | E10: 非主营 | F10: 欧洲海派-M | G10: 张诚 | I10: 马淞浦 | J10: 131.67 | K10: 103.47 | L10: 132 | M10: 132 | N10: 0
A11: SP260121220 | B11: ICBU00000932842 | C11: KP | D11: 加拿大海派-JY | E11: 非主营 | F11: 加拿大海派-JY | G11: 风清扬 | I11: 马淞浦 | J11: 66.78 | K11: 51.207 | L11: 67 | M11: 67 | N11: 0
A12: SP260120060 | B12: ICBU00000932975 | C12: KP | D12: 加拿大海派-JY | E12: 非主营 | F12: 加拿大海派-JY | G12: 风清扬 | I12: 马淞浦 | J12: 271.26 | K12: 187.498 | L12: 272 | M12: 272 | N12: 0
A13: SP260122050 | B13: ICBU00000932908 | C13: KP | D13: 加拿大海派-JY | E13: 非主营 | F13: 加拿大海派-JY | G13: 风清扬 | I13: 马淞浦 | J13: 136.99 | K13: 98.223 | L13: 138 | M13: 137 | N13: -1
A14: SP260122007 | B14: ICBU00000933117 | D14: 欧洲海派-M | E14: 非主营 | F14: 欧洲海派-M | G14: 张诚 | I14: 马淞浦 | J14: 124.82 | K14: 115.412 | L14: 125 | M14: 125 | N14: 0
A15: SP260121264 | B15: ICBU00000933138 | D15: 欧洲海派-M | E15: 非主营 | F15: 欧洲海派-M | G15: 张诚 | I15: 马淞浦 | J15: 233.25 | K15: 177.097 | L15: 234 | M15: 234 | N15: 0
A16: SP260121188 | B16: ICBU00000932970 | C16: KP | D16: 加拿大海派-JY | E16: 非主营 | F16: 加拿大海派-JY | G16: 风清扬 | I16: 马淞浦 | J16: 36.3 | K16: 28.373 | L16: 37 | M16: 37 | N16: 0
A17: SP260121174 | B17: ICBU00000932897 | C17: KP | D17: 加拿大海派-JY | E17: 非主营 | F17: 加拿大海派-JY | G17: 风清扬 | I17: 马淞浦 | J17: 25.91 | K17: 22.747 | L17: 26 | M17: 26 | N17: 0
A18: SP260121195 | B18: ICBU00000933111 | D18: 欧洲海派-M | E18: 非主营 | F18: 欧洲海派-M | G18: 张诚 | I18: 马淞浦 | J18: 40.95 | K18: 27.728 | L18: 41 | M18: 41 | N18: 0
A19: SP260121223 | B19: ICBU00000933110 | D19: 欧洲海派-M | E19: 非主营 | F19: 欧洲海派-M | G19: 张诚 | I19: 马淞浦 | J19: 312.72 | K19: 224.327 | L19: 313 | M19: 313 | N19: 0
A20: SP260120043-YYZ7-16 | B20: ICBU00000932894 | C20: KP | D20: 加拿大海派-JY | E20: 非主营 | F20: 加拿大海派-JY | G20: 风清扬 | I20: 马淞浦 | J20: 269 | K20: 200.901 | L20: 270 | M20: 269 | N20: -1
A21: SP260126064-YYZ7-38 | B21: ICBU00000932826 | C21: KP | D21: 加拿大海派-JY | E21: 非主营 | F21: 加拿大海派-JY | G21: 风清扬 | I21: 马淞浦 | J21: 730.44 | K21: 652.894 | L21: 732 | M21: 731 | N21: -1
A22: SP260112003 | B22: ICBU00000933121 | D22: 欧洲海派-M | E22: 非主营 | F22: 欧洲海派-M | G22: 张诚 | I22: 马淞浦 | J22: 633.45 | K22: 431.198 | L22: 634 | M22: 634 | N22: 0
A23: HCLSA0131-6 | B23: ICBU00000932498 | C23: TPL000134937 | D23: 澳大利亚海派-含税-SC | E23: 非主营 | F23: 澳大利亚海派-含税-SC | G23: 小旋风 | I23: 刘申奥 | J23: 36.48 | K23: 22.308 | L23: 37 | M23: 43 | N23: 6
A24: SP260121154 | B24: ICBU00000933112 | D24: 欧洲海派-M | E24: 非主营 | F24: 欧洲海派-M | G24: 张诚 | I24: 马淞浦 | J24: 502.74 | K24: 499.672 | L24: 503 | M24: 503 | N24: 0
A25: YKZXX013102 | B25: ICBU00000932200 | C25: 1ZA06B016832064447 | D25: 欧洲德国清专线 | E25: 非主营 | F25: 欧洲德国清专线 | G25: 小旋风 | I25: 张小雪 | J25: 51.07 | K25: 41.317 | L25: 52 | M25: 52 | N25: 0
A26: TM260131-1CA3 | B26: ICBU00000932388 | C26: 888386607575 | D26: OK-FDX-DHL-TNT | E26: 非主营 | F26: OK-FDX-DHL-TNT | G26: 玉麒麟 | I26: 邓健群 | J26: 0.72 | K26: 0 | L26: 1 | M26: 1 | N26: 0
A27: TM260131-2FR2 | B27: ICBU00000932359 | C27: 1ZA06B016818572639 | D27: 欧洲德国清专线 | E27: 非主营 | F27: 欧洲德国清专线 | G27: 小旋风 | I27: 邓健群 | J27: 29.31 | K27: 20.758 | L27: 30 | M27: 30 | N27: 0
A28: HH233M26 | B28: ICBU00000932242 | C28: 1ZF4K3596816247057 | D28: 欧洲专线-HMC | E28: 非主营 | F28: 欧洲专线-HMC | G28: 帅时莹 | I28: 李娟-业务 | J28: 189.88 | K28: 186.461 | L28: 208 | M28: 208 | N28: 0
A29: RSC3104 | B29: ICBU00000933165 | C29: 1Z0E465J0413832648 | D29: OK-FDX-DHL-TNT | E29: 非主营 | F29: OK-FDX-DHL-TNT | G29: 玉麒麟 | I29: 汪祺 | J29: 9.8 | K29: 6.919 | L29: 10 | M29: 10 | N29: 0
A30: RSC3103 | B30: ICBU00000933199 | C30: 1Z0E465J0419105235 | D30: OK-FDX-DHL-TNT | E30: 非主营 | F30: OK-FDX-DHL-TNT | G30: 玉麒麟 | I30: 汪祺 | J30: 9.83 | K30: 7.88 | L30: 10 | M30: 10 | N30: 0
A31: RSC3102 | B31: ICBU00000933162 | C31: 1Z0E465J0419058000 | D31: OK-FDX-DHL-TNT | E31: 非主营 | F31: OK-FDX-DHL-TNT | G31: 玉麒麟 | I31: 汪祺 | J31: 5.31 | K31: 4.997 | L31: 5.5 | M31: 5.5 | N31: 0
A32: RSC3101 | B32: ICBU00000933159 | C32: 1Z0E465J0415072448 | D32: OK-FDX-DHL-TNT | E32: 非主营 | F32: OK-FDX-DHL-TNT | G32: 玉麒麟 | I32: 汪祺 | J32: 6.37 | K32: 4.191 | L32: 6.5 | M32: 6.5 | N32: 0
A33: QLWJ1781704 | B33: ICBU00000932639 | C33: 1Z0E793D0422717448 | D33: OK-UPS红单 | E33: 非主营 | F33: OK-UPS红单 | G33: 玉麒麟 | I33: 宁春阳 | J33: 50.38 | K33: 52.836 | L33: 52 | M33: 56 | N33: 4
A34: JHZW7312 | B34: ICBU00000931347 | C34: 888384610822 | D34: OK-FDX-DHL-TNT | E34: 非主营 | F34: OK-FDX-DHL-TNT | G34: 玉麒麟 | I34: 宋海周 | J34: 28.04 | K34: 18.262 | L34: 29 | M34: 29 | N34: 0
A35: SH0131-2 | B35: ICBU00000932684 | C35: 1ZHF38642014756797 | D35: 加拿大准时达海派UPS | E35: 非主营 | F35: 加拿大准时达海派UPS | G35: 风清扬 | I35: 小飞侠 | J35: 16.97 | K35: 22.182 | L35: 27 | M35: 23 | N35: -4
A36: JPS20260131002 | B36: ICBU00000932924 | C36: CR431657742DE | D36: HST-UPS 6000 | E36: 非主营 | F36: HST-UPS 6000 | G36: 无崖子 | I36: 柴燕玲 | J36: 7.45 | K36: 9.281 | L36: 7.5 | M36: 9.5 | N36: 2
... A49: LM-056 | B49: ICBU00000932113 | C49: 1Z0R6D926806701789 | D49: 欧洲卡航含税(快递派) | E49: 非主营 | F49: 欧洲卡航含税(快递派） | G49: 007 | I49: 张小雪 | J49: 53.99 | K49: 53.065 | L49: 55 | M49: 54 | N49: -1
A50: YKZXX0131 | B50: ICBU00000932135 | D50: 义乌联邦IE-包税 | E50: 非主营 | F50: 义乌联邦IE-包税 | G50: 无崖子 | I50: 张小雪 | J50: 48.64 | K50: 113.528 | L50: 118 | M50: 122 | N50: 4
A51: HJ25613101 | B51: ICBU00000932738 | C51: 888401830517 | D51: JRGJ-专线 | E51: 非主营 | F51: JRGJ-专线 | G51: 帅时莹 | I51: 李凤 | J51: 69.65 | K51: 72.481 | L51: 82 | M51: 73 | N51: -9
A52: 29G6T9 | B52: ICBU00000933001 | C52: CR431656565DE | D52: HST-UPS 6000 | E52: 非主营 | F52: HST-UPS 6000 | G52: 无崖子 | I52: 李可 | J52: 12.39 | K52: 9.758 | L52: 12.5 | M52: 13 | N52: 0.5
...

Sheet 业务数据统计
A1: 期间 | B1: 渠道客服 | C1: 大货小货 | D1: 计算提成数据 | E1: 提成系数 | F1: 提成金额 | G1: 出货计费重 | H1: 是否计算提成 | I1: 客户单号 | J1: 服务商单号 | K1: 渠道转单号 | L1: 销售产品 | M1: 应收运费单价 | N1: 产品组 | O1: 结算员 | P1: 目的国家 | Q1: 邮编 | R1: FBA仓库代码 | S1: 客户 | T1: 客户类型 | U1: 业务员 | V1: 业务员部门 | W1: 前线客服 | X1: 申报总价值 | Y1: 货物类型 | Z1: 操作状态 | AA1: 中转状态 | AB1: 退件状态 | AC1: 件数 | AD1: 收货实重 | AE1: 收货计费重 | AF1: 收货比重 | AG1: 服务商计费重 | AH1: 应收 | AI1: 实收 | AJ1: 应收单价 | AK1: 应付 | AL1: 实付 | AM1: 毛利 | AN1: 业务员成本 | AO1: 业务员成本单价 | AP1: 业务员毛利 | AQ1: 产品部毛利 | AR1: 核销时间 | AS1: 应收是否锁定 | AT1: 应付是否锁定 | AU1: 结算服务商 | AV1: 业务服务商 | AW1: 服务渠道 | AX1: 收货机构 | AY1: 到货时间 | AZ1: 到货总单 | BA1: 出货时间 | BB1: 出货总单 | BC1: 附加服务 | BD1: 航空主单号 | BE1: 中文品名 | BF1: 自定义备注
A2: =MID(AY2,1,7) -> 2026-01 | B2: =_xlfn.XLOOKUP(I2,过机服务商重量差!A:A,过机服务商重量差!G:G) -> 玉麒麟 | C2: {=IF(N2="FBA","主营产品",IF(N2="专线","专线",LOOKUP(1,0/((G2>=提成标准!D:D)*(G2<提成标准!E:E)),提成标准!C:C)))} -> 快递小货 | D2: =IF(C2="快递小货",1,IF(C2="主营产品",0,G2)) -> 1 | E2: =_xlfn.XLOOKUP(C2,提成标准!C:C,提成标准!H:H,"") -> 2 | F2: =D2*E2 -> 2 | G2: =_xlfn.XLOOKUP(I2,过机服务商重量差!A:A,过机服务商重量差!L:L) -> 3.5 | H2: =IFERROR(LOOKUP(1,0/((B2=名单!B:B)*(VALUE(AY2)>=名单!E:E)*(VALUE(AY2)<=名单!G:G)*(AA2="正常走货")),名单!H:H),"否") -> 否 | I2: QS0131-MX | J2: 1ZG3325W0416448603 | L2: OK-FDX-DHL-TNT | N2: 非主营 | U2: 小飞侠 | V2: 营销五部 | AA2: 正常走货 | AQ2: 118.16 | AY2: 2026-01-31 22:46:57
A3: =MID(AY3,1,7) -> 2026-01 | B3: =_xlfn.XLOOKUP(I3,过机服务商重量差!A:A,过机服务商重量差!G:G) -> 玉麒麟 | C3: =IF(N3="FBA","主营产品",IF(N3="专线","专线",LOOKUP(1,0/((G3>=提成标准!D:D)*(G3<提成标准!E:E)),提成标准!C:C))) -> 快递小货 | D3: =IF(C3="快递小货",1,IF(C3="主营产品",0,G3)) -> 1 | E3: =_xlfn.XLOOKUP(C3,提成标准!C:C,提成标准!H:H,"") -> 2 | F3: =D3*E3 -> 2 | G3: =_xlfn.XLOOKUP(I3,过机服务商重量差!A:A,过机服务商重量差!L:L) -> 9.5 | H3: =IFERROR(LOOKUP(1,0/((B3=名单!B:B)*(VALUE(AY3)>=名单!E:E)*(VALUE(AY3)<=名单!G:G)*(AA3="正常走货")),名单!H:H),"否") -> 否 | I3: TL0131-NL | J3: 1Z4W260E0409673969 | L3: OK-UPS红单 | N3: 非主营 | U3: 小飞侠 | V3: 营销五部 | AA3: 正常走货 | AQ3: 132.4 | AY3: 2026-01-31 22:46:36
A4: =MID(AY4,1,7) -> 2026-01 | B4: =_xlfn.XLOOKUP(I4,过机服务商重量差!A:A,过机服务商重量差!G:G) -> 小旋风 | C4: =IF(N4="FBA","主营产品",IF(N4="专线","专线",LOOKUP(1,0/((G4>=提成标准!D:D)*(G4<提成标准!E:E)),提成标准!C:C))) -> 快递小货 | D4: =IF(C4="快递小货",1,IF(C4="主营产品",0,G4)) -> 1 | E4: =_xlfn.XLOOKUP(C4,提成标准!C:C,提成标准!H:H,"") -> 2 | F4: =D4*E4 -> 2 | G4: =_xlfn.XLOOKUP(I4,过机服务商重量差!A:A,过机服务商重量差!L:L) -> 0.7 | H4: =IFERROR(LOOKUP(1,0/((B4=名单!B:B)*(VALUE(AY4)>=名单!E:E)*(VALUE(AY4)<=名单!G:G)*(AA4="正常走货")),名单!H:H),"否") -> 否 | I4: FBA15G65R8GW | J4: RCD24000759946 | L4: 澳大利亚海派-包税 | N4: 非主营 | U4: 高雨晴 | V4: 营销二部 | AA4: 正常走货 | AQ4: 420 | AY4: 2026-01-31 22:45:45
A5: =MID(AY5,1,7) -> 2026-01 | B5: =_xlfn.XLOOKUP(I5,过机服务商重量差!A:A,过机服务商重量差!G:G) -> 小旋风 | C5: =IF(N5="FBA","主营产品",IF(N5="专线","专线",LOOKUP(1,0/((G5>=提成标准!D:D)*(G5<提成标准!E:E)),提成标准!C:C))) -> 快递小货 | D5: =IF(C5="快递小货",1,IF(C5="主营产品",0,G5)) -> 1 | E5: =_xlfn.XLOOKUP(C5,提成标准!C:C,提成标准!H:H,"") -> 2 | F5: =D5*E5 -> 2 | G5: =_xlfn.XLOOKUP(I5,过机服务商重量差!A:A,过机服务商重量差!L:L) -> 0.8 | H5: =IFERROR(LOOKUP(1,0/((B5=名单!B:B)*(VALUE(AY5)>=名单!E:E)*(VALUE(AY5)<=名单!G:G)*(AA5="正常走货")),名单!H:H),"否") -> 否 | I5: FBA15G65P13K | J5: RCD24000759947 | L5: 澳大利亚海派-包税 | N5: 非主营 | U5: 高雨晴 | V5: 营销二部 | AA5: 正常走货 | AQ5: 800 | AY5: 2026-01-31 22:45:28
A6: =MID(AY6,1,7) -> 2026-01 | B6: =_xlfn.XLOOKUP(I6,过机服务商重量差!A:A,过机服务商重量差!G:G) -> 张诚 | C6: =IF(N6="FBA","主营产品",IF(N6="专线","专线",LOOKUP(1,0/((G6>=提成标准!D:D)*(G6<提成标准!E:E)),提成标准!C:C))) -> 快递大货 | D6: =IF(C6="快递小货",1,IF(C6="主营产品",0,G6)) -> 44 | E6: =_xlfn.XLOOKUP(C6,提成标准!C:C,提成标准!H:H,"") -> 0.1 | F6: =D6*E6 -> 4.4 | G6: =_xlfn.XLOOKUP(I6,过机服务商重量差!A:A,过机服务商重量差!L:L) -> 44 | H6: =IFERROR(LOOKUP(1,0/((B6=名单!B:B)*(VALUE(AY6)>=名单!E:E)*(VALUE(AY6)<=名单!G:G)*(AA6="正常走货")),名单!H:H),"否") -> 否 | I6: SP260122021 | L6: 欧洲海卡包税-MM | N6: 非主营 | U6: 马淞浦 | V6: 营销一部 | AA6: 正常走货 | AQ6: 400 | AY6: 2026-01-31 22:43:03
A7: =MID(AY7,1,7) -> 2026-01 | B7: =_xlfn.XLOOKUP(I7,过机服务商重量差!A:A,过机服务商重量差!G:G) -> 张诚 | C7: =IF(N7="FBA","主营产品",IF(N7="专线","专线",LOOKUP(1,0/((G7>=提成标准!D:D)*(G7<提成标准!E:E)),提成标准!C:C))) -> 快递大货 | D7: =IF(C7="快递小货",1,IF(C7="主营产品",0,G7)) -> 236 | E7: =_xlfn.XLOOKUP(C7,提成标准!C:C,提成标准!H:H,"") -> 0.1 | F7: =D7*E7 -> 23.6 | G7: =_xlfn.XLOOKUP(I7,过机服务商重量差!A:A,过机服务商重量差!L:L) -> 236 | H7: =IFERROR(LOOKUP(1,0/((B7=名单!B:B)*(VALUE(AY7)>=名单!E:E)*(VALUE(AY7)<=名单!G:G)*(AA7="正常走货")),名单!H:H),"否") -> 否 | I7: SP260129024 | L7: 欧洲海卡包税-MM | N7: 非主营 | U7: 马淞浦 | V7: 营销一部 | AA7: 正常走货 | AQ7: 2832 | AY7: 2026-01-31 22:42:39
A8: =MID(AY8,1,7) -> 2026-01 | B8: =_xlfn.XLOOKUP(I8,过机服务商重量差!A:A,过机服务商重量差!G:G) -> 张诚 | C8: =IF(N8="FBA","主营产品",IF(N8="专线","专线",LOOKUP(1,0/((G8>=提成标准!D:D)*(G8<提成标准!E:E)),提成标准!C:C))) -> 快递大货 | D8: =IF(C8="快递小货",1,IF(C8="主营产品",0,G8)) -> 77 | E8: =_xlfn.XLOOKUP(C8,提成标准!C:C,提成标准!H:H,"") -> 0.1 | F8: =D8*E8 -> 7.7 | G8: =_xlfn.XLOOKUP(I8,过机服务商重量差!A:A,过机服务商重量差!L:L) -> 77 | H8: =IFERROR(LOOKUP(1,0/((B8=名单!B:B)*(VALUE(AY8)>=名单!E:E)*(VALUE(AY8)<=名单!G:G)*(AA8="正常走货")),名单!H:H),"否") -> 否 | I8: SP260121227 | L8: 欧洲海卡包税-MM | N8: 非主营 | U8: 马淞浦 | V8: 营销一部 | AA8: 正常走货 | AQ8: 924 | AY8: 2026-01-31 22:42:32
A9: =MID(AY9,1,7) -> 2026-01 | B9: =_xlfn.XLOOKUP(I9,过机服务商重量差!A:A,过机服务商重量差!G:G) -> 张诚 | C9: =IF(N9="FBA","主营产品",IF(N9="专线","专线",LOOKUP(1,0/((G9>=提成标准!D:D)*(G9<提成标准!E:E)),提成标准!C:C))) -> 快递大货 | D9: =IF(C9="快递小货",1,IF(C9="主营产品",0,G9)) -> 183 | E9: =_xlfn.XLOOKUP(C9,提成标准!C:C,提成标准!H:H,"") -> 0.1 | F9: =D9*E9 -> 18.3 | G9: =_xlfn.XLOOKUP(I9,过机服务商重量差!A:A,过机服务商重量差!L:L) -> 183 | H9: =IFERROR(LOOKUP(1,0/((B9=名单!B:B)*(VALUE(AY9)>=名单!E:E)*(VALUE(AY9)<=名单!G:G)*(AA9="正常走货")),名单!H:H),"否") -> 否 | I9: SP260123008 | L9: 欧洲海卡包税-MM | N9: 非主营 | U9: 马淞浦 | V9: 营销一部 | AA9: 正常走货 | AQ9: 2196 | AY9: 2026-01-31 22:40:53
A10: =MID(AY10,1,7) -> 2026-01 | B10: =_xlfn.XLOOKUP(I10,过机服务商重量差!A:A,过机服务商重量差!G:G) -> 张诚 | C10: =IF(N10="FBA","主营产品",IF(N10="专线","专线",LOOKUP(1,0/((G10>=提成标准!D:D)*(G10<提成标准!E:E)),提成标准!C:C))) -> 快递大货 | D10: =IF(C10="快递小货",1,IF(C10="主营产品",0,G10)) -> 132 | E10: =_xlfn.XLOOKUP(C10,提成标准!C:C,提成标准!H:H,"") -> 0.1 | F10: =D10*E10 -> 13.2 | G10: =_xlfn.XLOOKUP(I10,过机服务商重量差!A:A,过机服务商重量差!L:L) -> 132 | H10: =IFERROR(LOOKUP(1,0/((B10=名单!B:B)*(VALUE(AY10)>=名单!E:E)*(VALUE(AY10)<=名单!G:G)*(AA10="正常走货")),名单!H:H),"否") -> 否 | I10: SP260122003 | L10: 欧洲海卡包税-MM | N10: 非主营 | U10: 马淞浦 | V10: 营销一部 | AA10: 正常走货 | AQ10: 1584 | AY10: 2026-01-31 22:39:00
A11: =MID(AY11,1,7) -> 2026-01 | B11: =_xlfn.XLOOKUP(I11,过机服务商重量差!A:A,过机服务商重量差!G:G) -> 风清扬 | C11: =IF(N11="FBA","主营产品",IF(N11="专线","专线",LOOKUP(1,0/((G11>=提成标准!D:D)*(G11<提成标准!E:E)),提成标准!C:C))) -> 快递大货 | D11: =IF(C11="快递小货",1,IF(C11="主营产品",0,G11)) -> 67 | E11: =_xlfn.XLOOKUP(C11,提成标准!C:C,提成标准!H:H,"") -> 0.1 | F11: =D11*E11 -> 6.7 | G11: =_xlfn.XLOOKUP(I11,过机服务商重量差!A:A,过机服务商重量差!L:L) -> 67 | H11: =IFERROR(LOOKUP(1,0/((B11=名单!B:B)*(VALUE(AY11)>=名单!E:E)*(VALUE(AY11)<=名单!G:G)*(AA11="正常走货")),名单!H:H),"否") -> 否 | I11: SP260121220 | J11: KP | L11: 加拿大海派-JY | N11: 非主营 | U11: 马淞浦 | V11: 营销一部 | AA11: 正常走货 | AQ11: -99.5 | AY11: 2026-01-31 22:37:31
A12: =MID(AY12,1,7) -> 2026-01 | B12: =_xlfn.XLOOKUP(I12,过机服务商重量差!A:A,过机服务商重量差!G:G) -> 风清扬 | C12: =IF(N12="FBA","主营产品",IF(N12="专线","专线",LOOKUP(1,0/((G12>=提成标准!D:D)*(G12<提成标准!E:E)),提成标准!C:C))) -> 快递大货 | D12: =IF(C12="快递小货",1,IF(C12="主营产品",0,G12)) -> 272 | E12: =_xlfn.XLOOKUP(C12,提成标准!C:C,提成标准!H:H,"") -> 0.1 | F12: =D12*E12 -> 27.2 | G12: =_xlfn.XLOOKUP(I12,过机服务商重量差!A:A,过机服务商重量差!L:L) -> 272 | H12: =IFERROR(LOOKUP(1,0/((B12=名单!B:B)*(VALUE(AY12)>=名单!E:E)*(VALUE(AY12)<=名单!G:G)*(AA12="正常走货")),名单!H:H),"否") -> 否 | I12: SP260120060 | J12: KP | L12: 加拿大海派-JY | N12: 非主营 | U12: 马淞浦 | V12: 营销一部 | AA12: 正常走货 | AQ12: 126.4 | AY12: 2026-01-31 22:37:02
A13: =MID(AY13,1,7) -> 2026-01 | B13: =_xlfn.XLOOKUP(I13,过机服务商重量差!A:A,过机服务商重量差!G:G) -> 风清扬 | C13: =IF(N13="FBA","主营产品",IF(N13="专线","专线",LOOKUP(1,0/((G13>=提成标准!D:D)*(G13<提成标准!E:E)),提成标准!C:C))) -> 快递大货 | D13: =IF(C13="快递小货",1,IF(C13="主营产品",0,G13)) -> 138 | E13: =_xlfn.XLOOKUP(C13,提成标准!C:C,提成标准!H:H,"") -> 0.1 | F13: =D13*E13 -> 13.8 | G13: =_xlfn.XLOOKUP(I13,过机服务商重量差!A:A,过机服务商重量差!L:L) -> 138 | H13: =IFERROR(LOOKUP(1,0/((B13=名单!B:B)*(VALUE(AY13)>=名单!E:E)*(VALUE(AY13)<=名单!G:G)*(AA13="正常走货")),名单!H:H),"否") -> 否 | I13: SP260122050 | J13: KP | L13: 加拿大海派-JY | N13: 非主营 | U13: 马淞浦 | V13: 营销一部 | AA13: 正常走货 | AQ13: 139.3 | AY13: 2026-01-31 22:36:32
A14: =MID(AY14,1,7) -> 2026-01 | B14: =_xlfn.XLOOKUP(I14,过机服务商重量差!A:A,过机服务商重量差!G:G) -> 张诚 | C14: =IF(N14="FBA","主营产品",IF(N14="专线","专线",LOOKUP(1,0/((G14>=提成标准!D:D)*(G14<提成标准!E:E)),提成标准!C:C))) -> 快递大货 | D14: =IF(C14="快递小货",1,IF(C14="主营产品",0,G14)) -> 125 | E14: =_xlfn.XLOOKUP(C14,提成标准!C:C,提成标准!H:H,"") -> 0.1 | F14: =D14*E14 -> 12.5 | G14: =_xlfn.XLOOKUP(I14,过机服务商重量差!A:A,过机服务商重量差!L:L) -> 125 | H14: =IFERROR(LOOKUP(1,0/((B14=名单!B:B)*(VALUE(AY14)>=名单!E:E)*(VALUE(AY14)<=名单!G:G)*(AA14="正常走货")),名单!H:H),"否") -> 否 | I14: SP260122007 | L14: 欧洲海卡包税-MM | N14: 非主营 | U14: 马淞浦 | V14: 营销一部 | AA14: 正常走货 | AQ14: 1562.5 | AY14: 2026-01-31 22:31:06
A15: =MID(AY15,1,7) -> 2026-01 | B15: =_xlfn.XLOOKUP(I15,过机服务商重量差!A:A,过机服务商重量差!G:G) -> 张诚 | C15: =IF(N15="FBA","主营产品",IF(N15="专线","专线",LOOKUP(1,0/((G15>=提成标准!D:D)*(G15<提成标准!E:E)),提成标准!C:C))) -> 快递大货 | D15: =IF(C15="快递小货",1,IF(C15="主营产品",0,G15)) -> 234 | E15: =_xlfn.XLOOKUP(C15,提成标准!C:C,提成标准!H:H,"") -> 0.1 | F15: =D15*E15 -> 23.4 | G15: =_xlfn.XLOOKUP(I15,过机服务商重量差!A:A,过机服务商重量差!L:L) -> 234 | H15: =IFERROR(LOOKUP(1,0/((B15=名单!B:B)*(VALUE(AY15)>=名单!E:E)*(VALUE(AY15)<=名单!G:G)*(AA15="正常走货")),名单!H:H),"否") -> 否 | I15: SP260121264 | L15: 欧洲海卡包税-MM | N15: 非主营 | U15: 马淞浦 | V15: 营销一部 | AA15: 正常走货 | AQ15: 2925 | AY15: 2026-01-31 22:26:23
A16: =MID(AY16,1,7) -> 2026-01 | B16: =_xlfn.XLOOKUP(I16,过机服务商重量差!A:A,过机服务商重量差!G:G) -> 风清扬 | C16: =IF(N16="FBA","主营产品",IF(N16="专线","专线",LOOKUP(1,0/((G16>=提成标准!D:D)*(G16<提成标准!E:E)),提成标准!C:C))) -> 快递大货 | D16: =IF(C16="快递小货",1,IF(C16="主营产品",0,G16)) -> 37 | E16: =_xlfn.XLOOKUP(C16,提成标准!C:C,提成标准!H:H,"") -> 0.1 | F16: =D16*E16 -> 3.7 | G16: =_xlfn.XLOOKUP(I16,过机服务商重量差!A:A,过机服务商重量差!L:L) -> 37 | H16: =IFERROR(LOOKUP(1,0/((B16=名单!B:B)*(VALUE(AY16)>=名单!E:E)*(VALUE(AY16)<=名单!G:G)*(AA16="正常走货")),名单!H:H),"否") -> 否 | I16: SP260121188 | J16: KP | L16: 加拿大海派-JY | N16: 非主营 | U16: 马淞浦 | V16: 营销一部 | AA16: 正常走货 | AQ16: 29.9 | AY16: 2026-01-31 22:24:58
A17: =MID(AY17,1,7) -> 2026-01 | B17: =_xlfn.XLOOKUP(I17,过机服务商重量差!A:A,过机服务商重量差!G:G) -> 风清扬 | C17: =IF(N17="FBA","主营产品",IF(N17="专线","专线",LOOKUP(1,0/((G17>=提成标准!D:D)*(G17<提成标准!E:E)),提成标准!C:C))) -> 快递大货 | D17: =IF(C17="快递小货",1,IF(C17="主营产品",0,G17)) -> 26 | E17: =_xlfn.XLOOKUP(C17,提成标准!C:C,提成标准!H:H,"") -> 0.1 | F17: =D17*E17 -> 2.6 | G17: =_xlfn.XLOOKUP(I17,过机服务商重量差!A:A,过机服务商重量差!L:L) -> 26 | H17: =IFERROR(LOOKUP(1,0/((B17=名单!B:B)*(VALUE(AY17)>=名单!E:E)*(VALUE(AY17)<=名单!G:G)*(AA17="正常走货")),名单!H:H),"否") -> 否 | I17: SP260121174 | J17: KP | L17: 加拿大海派-JY | N17: 非主营 | U17: 马淞浦 | V17: 营销一部 | AA17: 正常走货 | AQ17: 173.4 | AY17: 2026-01-31 22:24:21
A18: =MID(AY18,1,7) -> 2026-01 | B18: =_xlfn.XLOOKUP(I18,过机服务商重量差!A:A,过机服务商重量差!G:G) -> 张诚 | C18: =IF(N18="FBA","主营产品",IF(N18="专线","专线",LOOKUP(1,0/((G18>=提成标准!D:D)*(G18<提成标准!E:E)),提成标准!C:C))) -> 快递大货 | D18: =IF(C18="快递小货",1,IF(C18="主营产品",0,G18)) -> 41 | E18: =_xlfn.XLOOKUP(C18,提成标准!C:C,提成标准!H:H,"") -> 0.1 | F18: =D18*E18 -> 4.1 | G18: =_xlfn.XLOOKUP(I18,过机服务商重量差!A:A,过机服务商重量差!L:L) -> 41 | H18: =IFERROR(LOOKUP(1,0/((B18=名单!B:B)*(VALUE(AY18)>=名单!E:E)*(VALUE(AY18)<=名单!G:G)*(AA18="正常走货")),名单!H:H),"否") -> 否 | I18: SP260121195 | L18: 欧洲海卡包税-MM | N18: 非主营 | U18: 马淞浦 | V18: 营销一部 | AA18: 正常走货 | AQ18: 594 | AY18: 2026-01-31 22:24:04
A19: =MID(AY19,1,7) -> 2026-01 | B19: =_xlfn.XLOOKUP(I19,过机服务商重量差!A:A,过机服务商重量差!G:G) -> 张诚 | C19: =IF(N19="FBA","主营产品",IF(N19="专线","专线",LOOKUP(1,0/((G19>=提成标准!D:D)*(G19<提成标准!E:E)),提成标准!C:C))) -> 快递大货 | D19: =IF(C19="快递小货",1,IF(C19="主营产品",0,G19)) -> 313 | E19: =_xlfn.XLOOKUP(C19,提成标准!C:C,提成标准!H:H,"") -> 0.1 | F19: =D19*E19 -> 31.3 | G19: =_xlfn.XLOOKUP(I19,过机服务商重量差!A:A,过机服务商重量差!L:L) -> 313 | H19: =IFERROR(LOOKUP(1,0/((B19=名单!B:B)*(VALUE(AY19)>=名单!E:E)*(VALUE(AY19)<=名单!G:G)*(AA19="正常走货")),名单!H:H),"否") -> 否 | I19: SP260121223 | L19: 欧洲海卡包税-MM | N19: 非主营 | U19: 马淞浦 | V19: 营销一部 | AA19: 正常走货 | AQ19: 4225.5 | AY19: 2026-01-31 22:20:47
A20: =MID(AY20,1,7) -> 2026-01 | B20: =_xlfn.XLOOKUP(I20,过机服务商重量差!A:A,过机服务商重量差!G:G) -> 风清扬 | C20: =IF(N20="FBA","主营产品",IF(N20="专线","专线",LOOKUP(1,0/((G20>=提成标准!D:D)*(G20<提成标准!E:E)),提成标准!C:C))) -> 快递大货 | D20: =IF(C20="快递小货",1,IF(C20="主营产品",0,G20)) -> 270 | E20: =_xlfn.XLOOKUP(C20,提成标准!C:C,提成标准!H:H,"") -> 0.1 | F20: =D20*E20 -> 27 | G20: =_xlfn.XLOOKUP(I20,过机服务商重量差!A:A,过机服务商重量差!L:L) -> 270 | H20: =IFERROR(LOOKUP(1,0/((B20=名单!B:B)*(VALUE(AY20)>=名单!E:E)*(VALUE(AY20)<=名单!G:G)*(AA20="正常走货")),名单!H:H),"否") -> 否 | I20: SP260120043-YYZ7-16 | J20: KP | L20: 加拿大海派-JY | N20: 非主营 | U20: 马淞浦 | V20: 营销一部 | AA20: 正常走货 | AQ20: -1287.4 | AY20: 2026-01-31 22:18:11
A21: =MID(AY21,1,7) -> 2026-01 | B21: =_xlfn.XLOOKUP(I21,过机服务商重量差!A:A,过机服务商重量差!G:G) -> 风清扬 | C21: =IF(N21="FBA","主营产品",IF(N21="专线","专线",LOOKUP(1,0/((G21>=提成标准!D:D)*(G21<提成标准!E:E)),提成标准!C:C))) -> 快递大货 | D21: =IF(C21="快递小货",1,IF(C21="主营产品",0,G21)) -> 732 | E21: =_xlfn.XLOOKUP(C21,提成标准!C:C,提成标准!H:H,"") -> 0.1 | F21: =D21*E21 -> 73.2 | G21: =_xlfn.XLOOKUP(I21,过机服务商重量差!A:A,过机服务商重量差!L:L) -> 732 | H21: =IFERROR(LOOKUP(1,0/((B21=名单!B:B)*(VALUE(AY21)>=名单!E:E)*(VALUE(AY21)<=名单!G:G)*(AA21="正常走货")),名单!H:H),"否") -> 否 | I21: SP260126064-YYZ7-38 | J21: KP | L21: 加拿大海派-JY | N21: 非主营 | U21: 马淞浦 | V21: 营销一部 | AA21: 正常走货 | AQ21: -2935.6 | AY21: 2026-01-31 22:17:08
A22: =MID(AY22,1,7) -> 2026-01 | B22: =_xlfn.XLOOKUP(I22,过机服务商重量差!A:A,过机服务商重量差!G:G) -> 张诚 | C22: =IF(N22="FBA","主营产品",IF(N22="专线","专线",LOOKUP(1,0/((G22>=提成标准!D:D)*(G22<提成标准!E:E)),提成标准!C:C))) -> 快递大货 | D22: =IF(C22="快递小货",1,IF(C22="主营产品",0,G22)) -> 634 | E22: =_xlfn.XLOOKUP(C22,提成标准!C:C,提成标准!H:H,"") -> 0.1 | F22: =D22*E22 -> 63.4 | G22: =_xlfn.XLOOKUP(I22,过机服务商重量差!A:A,过机服务商重量差!L:L) -> 634 | H22: =IFERROR(LOOKUP(1,0/((B22=名单!B:B)*(VALUE(AY22)>=名单!E:E)*(VALUE(AY22)<=名单!G:G)*(AA22="正常走货")),名单!H:H),"否") -> 否 | I22: SP260112003 | L22: 欧洲海卡包税-MM | N22: 非主营 | U22: 马淞浦 | V22: 营销一部 | AA22: 正常走货 | AQ22: 7975.8 | AY22: 2026-01-31 22:12:25
A23: =MID(AY23,1,7) -> 2026-01 | B23: =_xlfn.XLOOKUP(I23,过机服务商重量差!A:A,过机服务商重量差!G:G) -> 小旋风 | C23: =IF(N23="FBA","主营产品",IF(N23="专线","专线",LOOKUP(1,0/((G23>=提成标准!D:D)*(G23<提成标准!E:E)),提成标准!C:C))) -> 快递大货 | D23: =IF(C23="快递小货",1,IF(C23="主营产品",0,G23)) -> 37 | E23: =_xlfn.XLOOKUP(C23,提成标准!C:C,提成标准!H:H,"") -> 0.1 | F23: =D23*E23 -> 3.7 | G23: =_xlfn.XLOOKUP(I23,过机服务商重量差!A:A,过机服务商重量差!L:L) -> 37 | H23: =IFERROR(LOOKUP(1,0/((B23=名单!B:B)*(VALUE(AY23)>=名单!E:E)*(VALUE(AY23)<=名单!G:G)*(AA23="正常走货")),名单!H:H),"否") -> 否 | I23: HCLSA0131-6 | J23: TPL000134937 | L23: 澳大利亚海派-含税-SC | N23: 非主营 | U23: 刘申奥 | V23: 营销五部 | AA23: 正常走货 | AQ23: 195.9 | AY23: 2026-01-31 22:08:59
A24: =MID(AY24,1,7) -> 2026-01 | B24: =_xlfn.XLOOKUP(I24,过机服务商重量差!A:A,过机服务商重量差!G:G) -> 张诚 | C24: =IF(N24="FBA","主营产品",IF(N24="专线","专线",LOOKUP(1,0/((G24>=提成标准!D:D)*(G24<提成标准!E:E)),提成标准!C:C))) -> 快递大货 | D24: =IF(C24="快递小货",1,IF(C24="主营产品",0,G24)) -> 503 | E24: =_xlfn.XLOOKUP(C24,提成标准!C:C,提成标准!H:H,"") -> 0.1 | F24: =D24*E24 -> 50.3 | G24: =_xlfn.XLOOKUP(I24,过机服务商重量差!A:A,过机服务商重量差!L:L) -> 503 | H24: =IFERROR(LOOKUP(1,0/((B24=名单!B:B)*(VALUE(AY24)>=名单!E:E)*(VALUE(AY24)<=名单!G:G)*(AA24="正常走货")),名单!H:H),"否") -> 否 | I24: SP260121154 | L24: 欧洲海卡包税-MM | N24: 非主营 | U24: 马淞浦 | V24: 营销一部 | AA24: 正常走货 | AQ24: 6287.5 | AY24: 2026-01-31 22:01:04
A25: =MID(AY25,1,7) -> 2026-01 | B25: =_xlfn.XLOOKUP(I25,过机服务商重量差!A:A,过机服务商重量差!G:G) -> 小旋风 | C25: =IF(N25="FBA","主营产品",IF(N25="专线","专线",LOOKUP(1,0/((G25>=提成标准!D:D)*(G25<提成标准!E:E)),提成标准!C:C))) -> 快递大货 | D25: =IF(C25="快递小货",1,IF(C25="主营产品",0,G25)) -> 52 | E25: =_xlfn.XLOOKUP(C25,提成标准!C:C,提成标准!H:H,"") -> 0.1 | F25: =D25*E25 -> 5.2 | G25: =_xlfn.XLOOKUP(I25,过机服务商重量差!A:A,过机服务商重量差!L:L) -> 52 | H25: =IFERROR(LOOKUP(1,0/((B25=名单!B:B)*(VALUE(AY25)>=名单!E:E)*(VALUE(AY25)<=名单!G:G)*(AA25="正常走货")),名单!H:H),"否") -> 否 | I25: YKZXX013102 | J25: 1ZA06B016832064447 | L25: 欧洲德国清专线 | N25: 非主营 | U25: 张小雪 | V25: 营销五部 | AA25: 正常走货 | AQ25: 2794 | AY25: 2026-01-31 21:13:41
A26: =MID(AY26,1,7) -> 2026-01 | B26: =_xlfn.XLOOKUP(I26,过机服务商重量差!A:A,过机服务商重量差!G:G) -> 玉麒麟 | C26: =IF(N26="FBA","主营产品",IF(N26="专线","专线",LOOKUP(1,0/((G26>=提成标准!D:D)*(G26<提成标准!E:E)),提成标准!C:C))) -> 快递小货 | D26: =IF(C26="快递小货",1,IF(C26="主营产品",0,G26)) -> 1 | E26: =_xlfn.XLOOKUP(C26,提成标准!C:C,提成标准!H:H,"") -> 2 | F26: =D26*E26 -> 2 | G26: =_xlfn.XLOOKUP(I26,过机服务商重量差!A:A,过机服务商重量差!L:L) -> 1 | H26: =IFERROR(LOOKUP(1,0/((B26=名单!B:B)*(VALUE(AY26)>=名单!E:E)*(VALUE(AY26)<=名单!G:G)*(AA26="正常走货")),名单!H:H),"否") -> 否 | I26: TM260131-1CA3 | J26: 888386607575 | L26: OK-FDX-DHL-TNT | N26: 非主营 | U26: 邓健群 | V26: 营销三部 | AA26: 正常走货 | AQ26: 17.92 | AY26: 2026-01-31 21:02:14
A27: =MID(AY27,1,7) -> 2026-01 | B27: =_xlfn.XLOOKUP(I27,过机服务商重量差!A:A,过机服务商重量差!G:G) -> 小旋风 | C27: =IF(N27="FBA","主营产品",IF(N27="专线","专线",LOOKUP(1,0/((G27>=提成标准!D:D)*(G27<提成标准!E:E)),提成标准!C:C))) -> 快递大货 | D27: =IF(C27="快递小货",1,IF(C27="主营产品",0,G27)) -> 30 | E27: =_xlfn.XLOOKUP(C27,提成标准!C:C,提成标准!H:H,"") -> 0.1 | F27: =D27*E27 -> 3 | G27: =_xlfn.XLOOKUP(I27,过机服务商重量差!A:A,过机服务商重量差!L:L) -> 30 | H27: =IFERROR(LOOKUP(1,0/((B27=名单!B:B)*(VALUE(AY27)>=名单!E:E)*(VALUE(AY27)<=名单!G:G)*(AA27="正常走货")),名单!H:H),"否") -> 否 | I27: TM260131-2FR2 | J27: 1ZA06B016818572639 | L27: 欧洲德国清专线 | N27: 非主营 | U27: 邓健群 | V27: 营销三部 | AA27: 正常走货 | AQ27: 1500 | AY27: 2026-01-31 21:00:55
A28: =MID(AY28,1,7) -> 2026-01 | B28: =_xlfn.XLOOKUP(I28,过机服务商重量差!A:A,过机服务商重量差!G:G) -> 帅时莹 | C28: =IF(N28="FBA","主营产品",IF(N28="专线","专线",LOOKUP(1,0/((G28>=提成标准!D:D)*(G28<提成标准!E:E)),提成标准!C:C))) -> 快递大货 | D28: =IF(C28="快递小货",1,IF(C28="主营产品",0,G28)) -> 208 | E28: =_xlfn.XLOOKUP(C28,提成标准!C:C,提成标准!H:H,"") -> 0.1 | F28: =D28*E28 -> 20.8 | G28: =_xlfn.XLOOKUP(I28,过机服务商重量差!A:A,过机服务商重量差!L:L) -> 208 | H28: =IFERROR(LOOKUP(1,0/((B28=名单!B:B)*(VALUE(AY28)>=名单!E:E)*(VALUE(AY28)<=名单!G:G)*(AA28="正常走货")),名单!H:H),"否") -> 否 | I28: HH233M26 | J28: 1ZF4K3596816247057 | L28: 欧洲专线-HMC | N28: 非主营 | U28: 李娟-业务 | V28: 营销四部 | AA28: 正常走货 | AQ28: 2700 | AY28: 2026-01-31 20:59:02
A29: =MID(AY29,1,7) -> 2026-01 | B29: =_xlfn.XLOOKUP(I29,过机服务商重量差!A:A,过机服务商重量差!G:G) -> 玉麒麟 | C29: =IF(N29="FBA","主营产品",IF(N29="专线","专线",LOOKUP(1,0/((G29>=提成标准!D:D)*(G29<提成标准!E:E)),提成标准!C:C))) -> 快递小货 | D29: =IF(C29="快递小货",1,IF(C29="主营产品",0,G29)) -> 1 | E29: =_xlfn.XLOOKUP(C29,提成标准!C:C,提成标准!H:H,"") -> 2 | F29: =D29*E29 -> 2 | G29: =_xlfn.XLOOKUP(I29,过机服务商重量差!A:A,过机服务商重量差!L:L) -> 10 | H29: =IFERROR(LOOKUP(1,0/((B29=名单!B:B)*(VALUE(AY29)>=名单!E:E)*(VALUE(AY29)<=名单!G:G)*(AA29="正常走货")),名单!H:H),"否") -> 否 | I29: RSC3104 | J29: 1Z0E465J0413832648 | L29: OK-FDX-DHL-TNT | N29: 非主营 | U29: 汪祺 | V29: 营销二部 | AA29: 正常走货 | AQ29: 101.6 | AY29: 2026-01-31 20:56:27
A30: =MID(AY30,1,7) -> 2026-01 | B30: =_xlfn.XLOOKUP(I30,过机服务商重量差!A:A,过机服务商重量差!G:G) -> 玉麒麟 | C30: =IF(N30="FBA","主营产品",IF(N30="专线","专线",LOOKUP(1,0/((G30>=提成标准!D:D)*(G30<提成标准!E:E)),提成标准!C:C))) -> 快递小货 | D30: =IF(C30="快递小货",1,IF(C30="主营产品",0,G30)) -> 1 | E30: =_xlfn.XLOOKUP(C30,提成标准!C:C,提成标准!H:H,"") -> 2 | F30: =D30*E30 -> 2 | G30: =_xlfn.XLOOKUP(I30,过机服务商重量差!A:A,过机服务商重量差!L:L) -> 10 | H30: =IFERROR(LOOKUP(1,0/((B30=名单!B:B)*(VALUE(AY30)>=名单!E:E)*(VALUE(AY30)<=名单!G:G)*(AA30="正常走货")),名单!H:H),"否") -> 否 | I30: RSC3103 | J30: 1Z0E465J0419105235 | L30: OK-FDX-DHL-TNT | N30: 非主营 | U30: 汪祺 | V30: 营销二部 | AA30: 正常走货 | AQ30: 101.6 | AY30: 2026-01-31 20:56:22
A31: =MID(AY31,1,7) -> 2026-01 | B31: =_xlfn.XLOOKUP(I31,过机服务商重量差!A:A,过机服务商重量差!G:G) -> 玉麒麟 | C31: =IF(N31="FBA","主营产品",IF(N31="专线","专线",LOOKUP(1,0/((G31>=提成标准!D:D)*(G31<提成标准!E:E)),提成标准!C:C))) -> 快递小货 | D31: =IF(C31="快递小货",1,IF(C31="主营产品",0,G31)) -> 1 | E31: =_xlfn.XLOOKUP(C31,提成标准!C:C,提成标准!H:H,"") -> 2 | F31: =D31*E31 -> 2 | G31: =_xlfn.XLOOKUP(I31,过机服务商重量差!A:A,过机服务商重量差!L:L) -> 5.5 | H31: =IFERROR(LOOKUP(1,0/((B31=名单!B:B)*(VALUE(AY31)>=名单!E:E)*(VALUE(AY31)<=名单!G:G)*(AA31="正常走货")),名单!H:H),"否") -> 否 | I31: RSC3102 | J31: 1Z0E465J0419058000 | L31: OK-FDX-DHL-TNT | N31: 非主营 | U31: 汪祺 | V31: 营销二部 | AA31: 正常走货 | AQ31: 101.6 | AY31: 2026-01-31 20:56:04
A32: =MID(AY32,1,7) -> 2026-01 | B32: =_xlfn.XLOOKUP(I32,过机服务商重量差!A:A,过机服务商重量差!G:G) -> 玉麒麟 | C32: =IF(N32="FBA","主营产品",IF(N32="专线","专线",LOOKUP(1,0/((G32>=提成标准!D:D)*(G32<提成标准!E:E)),提成标准!C:C))) -> 快递小货 | D32: =IF(C32="快递小货",1,IF(C32="主营产品",0,G32)) -> 1 | E32: =_xlfn.XLOOKUP(C32,提成标准!C:C,提成标准!H:H,"") -> 2 | F32: =D32*E32 -> 2 | G32: =_xlfn.XLOOKUP(I32,过机服务商重量差!A:A,过机服务商重量差!L:L) -> 6.5 | H32: =IFERROR(LOOKUP(1,0/((B32=名单!B:B)*(VALUE(AY32)>=名单!E:E)*(VALUE(AY32)<=名单!G:G)*(AA32="正常走货")),名单!H:H),"否") -> 否 | I32: RSC3101 | J32: 1Z0E465J0415072448 | L32: OK-FDX-DHL-TNT | N32: 非主营 | U32: 汪祺 | V32: 营销二部 | AA32: 正常走货 | AQ32: 101.6 | AY32: 2026-01-31 20:55:58
A33: =MID(AY33,1,7) -> 2026-01 | B33: =_xlfn.XLOOKUP(I33,过机服务商重量差!A:A,过机服务商重量差!G:G) -> 玉麒麟 | C33: =IF(N33="FBA","主营产品",IF(N33="专线","专线",LOOKUP(1,0/((G33>=提成标准!D:D)*(G33<提成标准!E:E)),提成标准!C:C))) -> 快递大货 | D33: =IF(C33="快递小货",1,IF(C33="主营产品",0,G33)) -> 52 | E33: =_xlfn.XLOOKUP(C33,提成标准!C:C,提成标准!H:H,"") -> 0.1 | F33: =D33*E33 -> 5.2 | G33: =_xlfn.XLOOKUP(I33,过机服务商重量差!A:A,过机服务商重量差!L:L) -> 52 | H33: =IFERROR(LOOKUP(1,0/((B33=名单!B:B)*(VALUE(AY33)>=名单!E:E)*(VALUE(AY33)<=名单!G:G)*(AA33="正常走货")),名单!H:H),"否") -> 否 | I33: QLWJ1781704 | J33: 1Z0E793D0422717448 | L33: OK-UPS红单 | N33: 非主营 | U33: 宁春阳 | V33: 营销二部 | AA33: 正常走货 | AQ33: 421.1 | AY33: 2026-01-31 20:53:03
A34: =MID(AY34,1,7) -> 2026-01 | B34: =_xlfn.XLOOKUP(I34,过机服务商重量差!A:A,过机服务商重量差!G:G) -> 玉麒麟 | C34: =IF(N34="FBA","主营产品",IF(N34="专线","专线",LOOKUP(1,0/((G34>=提成标准!D:D)*(G34<提成标准!E:E)),提成标准!C:C))) -> 快递大货 | D34: =IF(C34="快递小货",1,IF(C34="主营产品",0,G34)) -> 29 | E34: =_xlfn.XLOOKUP(C34,提成标准!C:C,提成标准!H:H,"") -> 0.1 | F34: =D34*E34 -> 2.9 | G34: =_xlfn.XLOOKUP(I34,过机服务商重量差!A:A,过机服务商重量差!L:L) -> 29 | H34: =IFERROR(LOOKUP(1,0/((B34=名单!B:B)*(VALUE(AY34)>=名单!E:E)*(VALUE(AY34)<=名单!G:G)*(AA34="正常走货")),名单!H:H),"否") -> 否 | I34: JHZW7312 | J34: 888384610822 | L34: OK-FDX-DHL-TNT | N34: 非主营 | U34: 宋海周 | V34: 营销二部 | AA34: 正常走货 | AQ34: 101.64 | AY34: 2026-01-31 20:46:55
A35: =MID(AY35,1,7) -> 2026-01 | B35: =_xlfn.XLOOKUP(I35,过机服务商重量差!A:A,过机服务商重量差!G:G) -> 风清扬 | C35: =IF(N35="FBA","主营产品",IF(N35="专线","专线",LOOKUP(1,0/((G35>=提成标准!D:D)*(G35<提成标准!E:E)),提成标准!C:C))) -> 快递大货 | D35: =IF(C35="快递小货",1,IF(C35="主营产品",0,G35)) -> 27 | E35: =_xlfn.XLOOKUP(C35,提成标准!C:C,提成标准!H:H,"") -> 0.1 | F35: =D35*E35 -> 2.7 | G35: =_xlfn.XLOOKUP(I35,过机服务商重量差!A:A,过机服务商重量差!L:L) -> 27 | H35: =IFERROR(LOOKUP(1,0/((B35=名单!B:B)*(VALUE(AY35)>=名单!E:E)*(VALUE(AY35)<=名单!G:G)*(AA35="正常走货")),名单!H:H),"否") -> 否 | I35: SH0131-2 | J35: 1ZHF38642014756797 | L35: 加拿大准时达海派UPS | N35: 非主营 | U35: 小飞侠 | V35: 营销五部 | AA35: 正常走货 | AQ35: 377 | AY35: 2026-01-31 20:43:24
A36: =MID(AY36,1,7) -> 2026-01 | B36: =_xlfn.XLOOKUP(I36,过机服务商重量差!A:A,过机服务商重量差!G:G) -> 无崖子 | C36: {=IF(N36="FBA","主营产品",IF(N36="专线","专线",LOOKUP(1,0/((G36>=提成标准!D:D)*(G36<提成标准!E:E)),提成标准!C:C)))} -> 快递小货 | D36: =IF(C36="快递小货",1,IF(C36="主营产品",0,G36)) -> 1 | E36: =_xlfn.XLOOKUP(C36,提成标准!C:C,提成标准!H:H,"") -> 2 | F36: =D36*E36 -> 2 | G36: =_xlfn.XLOOKUP(I36,过机服务商重量差!A:A,过机服务商重量差!L:L) -> 7.5 | H36: =IFERROR(LOOKUP(1,0/((B36=名单!B:B)*(VALUE(AY36)>=名单!E:E)*(VALUE(AY36)<=名单!G:G)*(AA36="正常走货")),名单!H:H),"否") -> 是 | I36: JPS20260131002 | J36: CR431657742DE | L36: HST-UPS 6000 | N36: 非主营 | U36: 柴燕玲 | V36: 四部KA客服 | AA36: 正常走货 | AQ36: 225 | AY36: 2026-01-31 20:41:12
A37: =MID(AY37,1,7) -> 2026-01 | B37: =_xlfn.XLOOKUP(I37,过机服务商重量差!A:A,过机服务商重量差!G:G) -> 无崖子 | C37: =IF(N37="FBA","主营产品",IF(N37="专线","专线",LOOKUP(1,0/((G37>=提成标准!D:D)*(G37<提成标准!E:E)),提成标准!C:C))) -> 快递小货 | D37: =IF(C37="快递小货",1,IF(C37="主营产品",0,G37)) -> 1 | E37: =_xlfn.XLOOKUP(C37,提成标准!C:C,提成标准!H:H,"") -> 2 | F37: =D37*E37 -> 2 | G37: =_xlfn.XLOOKUP(I37,过机服务商重量差!A:A,过机服务商重量差!L:L) -> 6 | H37: =IFERROR(LOOKUP(1,0/((B37=名单!B:B)*(VALUE(AY37)>=名单!E:E)*(VALUE(AY37)<=名单!G:G)*(AA37="正常走货")),名单!H:H),"否") -> 是 | I37: JPS20260131001 | J37: CR431657314DE | L37: HST-UPS 6000 | N37: 非主营 | U37: 柴燕玲 | V37: 四部KA客服 | AA37: 正常走货 | AQ37: 229.36 | AY37: 2026-01-31 20:41:04
A38: =MID(AY38,1,7) -> 2026-01 | B38: =_xlfn.XLOOKUP(I38,过机服务商重量差!A:A,过机服务商重量差!G:G) -> 玉麒麟 | C38: =IF(N38="FBA","主营产品",IF(N38="专线","专线",LOOKUP(1,0/((G38>=提成标准!D:D)*(G38<提成标准!E:E)),提成标准!C:C))) -> 快递大货 | D38: =IF(C38="快递小货",1,IF(C38="主营产品",0,G38)) -> 25 | E38: =_xlfn.XLOOKUP(C38,提成标准!C:C,提成标准!H:H,"") -> 0.1 | F38: =D38*E38 -> 2.5 | G38: =_xlfn.XLOOKUP(I38,过机服务商重量差!A:A,过机服务商重量差!L:L) -> 25 | H38: =IFERROR(LOOKUP(1,0/((B38=名单!B:B)*(VALUE(AY38)>=名单!E:E)*(VALUE(AY38)<=名单!G:G)*(AA38="正常走货")),名单!H:H),"否") -> 否 | I38: PBI3-FBA19757N66N | J38: 1Z0E465J0407453337 | L38: OK-FDX-DHL-TNT | N38: 非主营 | U38: 李娟-业务 | V38: 营销四部 | AA38: 正常走货 | AQ38: 329.1 | AY38: 2026-01-31 20:40:50
A39: =MID(AY39,1,7) -> 2026-01 | B39: =_xlfn.XLOOKUP(I39,过机服务商重量差!A:A,过机服务商重量差!G:G) -> 帅时莹 | C39: =IF(N39="FBA","主营产品",IF(N39="专线","专线",LOOKUP(1,0/((G39>=提成标准!D:D)*(G39<提成标准!E:E)),提成标准!C:C))) -> 快递小货 | D39: =IF(C39="快递小货",1,IF(C39="主营产品",0,G39)) -> 1 | E39: =_xlfn.XLOOKUP(C39,提成标准!C:C,提成标准!H:H,"") -> 2 | F39: =D39*E39 -> 2 | G39: =_xlfn.XLOOKUP(I39,过机服务商重量差!A:A,过机服务商重量差!L:L) -> 3.5 | H39: =IFERROR(LOOKUP(1,0/((B39=名单!B:B)*(VALUE(AY39)>=名单!E:E)*(VALUE(AY39)<=名单!G:G)*(AA39="正常走货")),名单!H:H),"否") -> 否 | I39: 95T6963 | J39: 1ZG3333D0406480200 | L39: MSHQ-UPS | N39: 非主营 | U39: 李娟-业务 | V39: 营销四部 | AA39: 正常走货 | AQ39: 139.1 | AY39: 2026-01-31 20:40:36
A40: =MID(AY40,1,7) -> 2026-01 | B40: =_xlfn.XLOOKUP(I40,过机服务商重量差!A:A,过机服务商重量差!G:G) -> 风清扬 | C40: =IF(N40="FBA","主营产品",IF(N40="专线","专线",LOOKUP(1,0/((G40>=提成标准!D:D)*(G40<提成标准!E:E)),提成标准!C:C))) -> 快递大货 | D40: =IF(C40="快递小货",1,IF(C40="主营产品",0,G40)) -> 142 | E40: =_xlfn.XLOOKUP(C40,提成标准!C:C,提成标准!H:H,"") -> 0.1 | F40: =D40*E40 -> 14.2 | G40: =_xlfn.XLOOKUP(I40,过机服务商重量差!A:A,过机服务商重量差!L:L) -> 142 | H40: =IFERROR(LOOKUP(1,0/((B40=名单!B:B)*(VALUE(AY40)>=名单!E:E)*(VALUE(AY40)<=名单!G:G)*(AA40="正常走货")),名单!H:H),"否") -> 否 | I40: 24543733501033648 | J40: 881072500 | L40: 东南亚专线 | N40: 非主营 | U40: 丁佳伟 | V40: 营销三部 | AA40: 正常走货 | AQ40: 1361 | AY40: 2026-01-31 20:40:27
...

Sheet 名单
A1: 姓名 | B1: 客服系统名 | C1: 姓名 | D1: 入职时间 | E1: 提成计算开始日期 | F1: 结束日期（手填） | G1: 结束日期 | H1: 是否计算提成
B2: 无崖子 | C2: 陈巧玲 | E2: 45078 | G2: =IF(F2="",TODAY(),F2) -> 46114 | H2: 是
B3: 霹雳火-快递客服(杨帆) | C3: 杨帆 | E3: 45123 | F3: 45276 | G3: =IF(F3="",TODAY(),F3) -> 45276 | H3: 是

Sheet 提成标准
A2: 渠道 | B2: 中转状态 | D2: 大于等于 | E2: 小于 | F2: 取数 | G2: 单位 | H2: 提成系数（元） | N2: 渠道 | O2: 中转状态 | Q2: 大于等于 | R2: 小于 | S2: 取数 | T2: 单位 | U2: 提成系数（元） | V2: 截止到2023.12.14（其中杨帆的是到离职日16日）
A3: 快递 | B3: 正常走货 | C3: 快递小货 | D3: 0 | E3: 21 | F3: 1 | G3: 票 | H3: 2 | I3: 2元/票 | N3: 快递 | O3: 正常走货 | P3: 快递小货 | Q3: 0 | R3: 21 | S3: 1 | T3: 票 | U3: 2 | V3: 2元/票
A4: 快递 | B4: 正常走货 | C4: 快递大货 | D4: 21 | E4: 99999 | F4: 出货计费重 | G4: KG | H4: 0.1 | I4: 0.1元/KG | N4: 快递 | O4: 正常走货 | P4: 快递大货 | Q4: 21 | R4: 99999 | S4: 出货计费重 | T4: KG | U4: 0.2 | V4: 0.2元/KG
A5: 专线 | B5: 正常走货 | C5: 专线 | F5: 出货计费重 | G5: KG | H5: 0.1 | I5: 0.1元/KG | N5: 专线 | O5: 正常走货 | P5: 专线 | S5: 出货计费重 | T5: KG | U5: 0.1 | V5: 0.1元/KG
A6: 主营产品 | C6: 主营产品 | H6: 0 | N6: 主营产品 | P6: 主营产品 | U6: 0
N8: 渠道 | O8: 中转状态 | Q8: 大于等于 | R8: 小于 | S8: 取数 | T8: 单位 | U8: 提成系数（元） | V8: 2023.12.15开始
N9: 快递 | O9: 正常走货 | P9: 快递小货 | Q9: 0 | R9: 21 | S9: 1 | T9: 票 | U9: 2 | V9: 2元/票
N10: 快递 | O10: 正常走货 | P10: 快递大货 | Q10: 21 | R10: 99999 | S10: 出货计费重 | T10: KG | U10: 0.1 | V10: 0.1元/KG
N11: 专线 | O11: 正常走货 | P11: 专线 | S11: 出货计费重 | T11: KG | U11: 0.1 | V11: 0.1元/KG
N12: 主营产品 | P12: 主营产品 | U12: 0

Sheet 特殊事项扣除
A1: 扣除期间 | B1: 客服名 | C1: 扣除金额 | D1: 单号期间 | E1: 备注 | F1: 单号
A2: 2023-07 | B2: 霹雳火-快递客服(杨帆) | C2: 724.12 | D2: 45110 | F2: TJ01532 | G2: =_xlfn.DISPIMG("ID_9F528AFC3D734C0F93B5BDB826E0677E",1) -> =DISPIMG("ID_9F528AFC3D734C0F93B5BDB826E0677E",1)
A3: 2023-08 | B3: 霹雳火-快递客服(杨帆) | C3: 0.7
A4: 2023-08 | B4: 霹雳火-快递客服(杨帆) | C4: 0.7
A5: 2023-08 | B5: 霹雳火-快递客服(杨帆) | C5: 0.71
A6: 2023-08 | B6: 霹雳火-快递客服(杨帆) | C6: 8.27
A7: 2023-08 | B7: 霹雳火-快递客服(杨帆) | C7: 14.68
A8: 2023-08 | B8: 霹雳火-快递客服(杨帆) | C8: 0.01
A9: 2023-08 | B9: 霹雳火-快递客服(杨帆) | C9: 10.69
A10: 2023-08 | B10: 霹雳火-快递客服(杨帆) | C10: 10.69
A11: 2023-08 | B11: 霹雳火-快递客服(杨帆) | C11: 13.35
A12: 2023-08 | B12: 霹雳火-快递客服(杨帆) | C12: 0.01
A13: 2023-08 | B13: 霹雳火-快递客服(杨帆) | C13: 12.69
A14: 2023-08 | B14: 霹雳火-快递客服(杨帆) | C14: 11.35
... A79: 2023-08 | B79: 霹雳火-快递客服(杨帆) | C79: 17.43

Sheet 提成
A1: 渠道客服提成明细表
D2: 快递小货 | E2: 快递大货 | F2: 专线 | G2: 快递小货 | H2: 快递大货 | I2: 专线 | J2: 快递小货 | K2: 快递大货 | L2: 专线
A3: 客服系统名 | B3: 姓名 | C3: 期间 | D3: 快递小货 票数 | E3: 快递大货 出货计费重 | F3: 专线 出货计费重 | G3: 快递小货 提成系数 | H3: 快递大货 提成系数 | I3: 专线 提成系数 | J3: 快递小货 提成 | K3: 快递大货 提成 | L3: 专线 提成 | M3: 应发提成 合计 | N3: 特殊事项扣除 | O3: 实发 提成
A4: 无崖子 | C4: =业务员明细!F1 -> 2026-01 | D4: =COUNTIFS(业务数据统计!$C:$C,$D$2,业务数据统计!$H:$H,"是",业务数据统计!$B:$B,$A4) -> 583 | E4: =SUMIFS(业务数据统计!$G:$G,业务数据统计!$C:$C,E$2,业务数据统计!$B:$B,$A4,业务数据统计!$H:$H,"是") -> 11759.5 | F4: =SUMIFS(业务数据统计!$G:$G,业务数据统计!$C:$C,F$2,业务数据统计!$B:$B,$A4,业务数据统计!$H:$H,"是") -> 0 | G4: =_xlfn.XLOOKUP(G$2,提成标准!$C:$C,提成标准!$H:$H) -> 2 | H4: =_xlfn.XLOOKUP(H$2,提成标准!$C:$C,提成标准!$H:$H) -> 0.1 | I4: =_xlfn.XLOOKUP(I$2,提成标准!$C:$C,提成标准!$H:$H) -> 0.1 | J4: =D4*G4 -> 1166 | K4: =H4*E4 -> 1175.95 | L4: =I4*F4 -> 0 | M4: =SUM(J4:L4) -> 2341.95 | N4: =SUMIFS(特殊事项扣除!C:C,特殊事项扣除!A:A,C4,特殊事项扣除!B:B,A4) -> 0 | O4: =M4-N4 -> 2341.95 | P4: 其中发给江雯756元，剩余的是渠道部的成本
A5: 合计： | D5: =SUM(D4:D4) -> 583 | E5: =SUM(E4:E4) -> 11759.5 | F5: =SUM(F4:F4) -> 0 | G5: =_xlfn.XLOOKUP(G$2,提成标准!$C:$C,提成标准!$H:$H) -> 2 | H5: =_xlfn.XLOOKUP(H$2,提成标准!$C:$C,提成标准!$H:$H) -> 0.1 | I5: =_xlfn.XLOOKUP(I$2,提成标准!$C:$C,提成标准!$H:$H) -> 0.1 | J5: =SUM(J4:J4) -> 1166 | K5: =SUM(K4:K4) -> 1175.95 | L5: =SUM(L4:L4) -> 0 | M5: =SUM(M4:M4) -> 2341.95 | N5: =SUM(N4:N4) -> 0 | O5: =SUM(O4:O4) -> 2341.95
N7: 制表人：
I12: 此表是渠道部提成数据，只登记，但不发放提成 | N12: 目前是按照江雯的单独提成制度发给江雯提成

Sheet 业务员明细
A1: 渠道客服提成明细表（业务员承担） | F1: 2026-01
A2: 系统名 | B2: 部门 | C2: 运单期间 | D2: 承担金额 | E2: 部门
A3: 柴燕玲 | B3: =_xlfn.XLOOKUP(E3,部门!A:A,部门!B:B) -> 销售四部 | C3: =$F$1 -> 2026-01 | D3: =SUMIFS(业务数据统计!F:F,业务数据统计!U:U,A3,业务数据统计!H:H,"是") -> 62.5 | E3: =_xlfn.XLOOKUP(A3,业务数据统计!U:U,业务数据统计!V:V,"") -> 四部KA客服
A4: 冯青青 | B4: =_xlfn.XLOOKUP(E4,部门!A:A,部门!B:B) -> 销售五部 | C4: =$F$1 -> 2026-01 | D4: =SUMIFS(业务数据统计!F:F,业务数据统计!U:U,A4,业务数据统计!H:H,"是") -> 177 | E4: =_xlfn.XLOOKUP(A4,业务数据统计!U:U,业务数据统计!V:V,"") -> 营销五部
A5: 张小雪 | B5: =_xlfn.XLOOKUP(E5,部门!A:A,部门!B:B) -> 销售五部 | C5: =$F$1 -> 2026-01 | D5: =SUMIFS(业务数据统计!F:F,业务数据统计!U:U,A5,业务数据统计!H:H,"是") -> 216.1 | E5: =_xlfn.XLOOKUP(A5,业务数据统计!U:U,业务数据统计!V:V,"") -> 营销五部
A6: 李可 | B6: =_xlfn.XLOOKUP(E6,部门!A:A,部门!B:B) -> 销售四部 | C6: =$F$1 -> 2026-01 | D6: =SUMIFS(业务数据统计!F:F,业务数据统计!U:U,A6,业务数据统计!H:H,"是") -> 238.5 | E6: =_xlfn.XLOOKUP(A6,业务数据统计!U:U,业务数据统计!V:V,"") -> 营销四部
A7: 臧明 | B7: =_xlfn.XLOOKUP(E7,部门!A:A,部门!B:B) -> 销售四部 | C7: =$F$1 -> 2026-01 | D7: =SUMIFS(业务数据统计!F:F,业务数据统计!U:U,A7,业务数据统计!H:H,"是") -> 93.9 | E7: =_xlfn.XLOOKUP(A7,业务数据统计!U:U,业务数据统计!V:V,"") -> 北苑总经办
A8: 施建祥 | B8: =_xlfn.XLOOKUP(E8,部门!A:A,部门!B:B) -> 销售三部 | C8: =$F$1 -> 2026-01 | D8: =SUMIFS(业务数据统计!F:F,业务数据统计!U:U,A8,业务数据统计!H:H,"是") -> 6 | E8: =_xlfn.XLOOKUP(A8,业务数据统计!U:U,业务数据统计!V:V,"") -> 营销三部 | G8: 杭州 | H8: =SUMIFS(D:D,B:B,G8) -> 2
A9: 陈颖 | B9: =_xlfn.XLOOKUP(E9,部门!A:A,部门!B:B) -> 销售五部 | C9: =$F$1 -> 2026-01 | D9: =SUMIFS(业务数据统计!F:F,业务数据统计!U:U,A9,业务数据统计!H:H,"是") -> 215.6 | E9: =_xlfn.XLOOKUP(A9,业务数据统计!U:U,业务数据统计!V:V,"") -> 营销五部 | G9: 宁波 | H9: =SUMIFS(D:D,B:B,G9) -> 8.5
A10: 高雨晴 | B10: =_xlfn.XLOOKUP(E10,部门!A:A,部门!B:B) -> 销售二部 | C10: =$F$1 -> 2026-01 | D10: =SUMIFS(业务数据统计!F:F,业务数据统计!U:U,A10,业务数据统计!H:H,"是") -> 6 | E10: =_xlfn.XLOOKUP(A10,业务数据统计!U:U,业务数据统计!V:V,"") -> 营销二部 | G10: 台州 | H10: =SUMIFS(D:D,B:B,G10) -> 2
A11: 张雪 | B11: =_xlfn.XLOOKUP(E11,部门!A:A,部门!B:B) -> 销售四部 | C11: =$F$1 -> 2026-01 | D11: =SUMIFS(业务数据统计!F:F,业务数据统计!U:U,A11,业务数据统计!H:H,"是") -> 56.5 | E11: =_xlfn.XLOOKUP(A11,业务数据统计!U:U,业务数据统计!V:V,"") -> 营销四部 | G11: 销售二部 | H11: =SUMIFS(D:D,B:B,G11) -> 118.6
A12: 丁佳伟 | B12: =_xlfn.XLOOKUP(E12,部门!A:A,部门!B:B) -> 销售三部 | C12: =$F$1 -> 2026-01 | D12: =SUMIFS(业务数据统计!F:F,业务数据统计!U:U,A12,业务数据统计!H:H,"是") -> 286.9 | E12: =_xlfn.XLOOKUP(A12,业务数据统计!U:U,业务数据统计!V:V,"") -> 营销三部 | G12: 销售三部 | H12: =SUMIFS(D:D,B:B,G12) -> 503.5
A13: 黄小丽 | B13: =_xlfn.XLOOKUP(E13,部门!A:A,部门!B:B) -> 销售四部 | C13: =$F$1 -> 2026-01 | D13: =SUMIFS(业务数据统计!F:F,业务数据统计!U:U,A13,业务数据统计!H:H,"是") -> 8 | E13: =_xlfn.XLOOKUP(A13,业务数据统计!U:U,业务数据统计!V:V,"") -> 营销四部 | G13: 销售四部 | H13: =SUMIFS(D:D,B:B,G13) -> 765.4
A14: 宋海周 | B14: =_xlfn.XLOOKUP(E14,部门!A:A,部门!B:B) -> 销售二部 | C14: =$F$1 -> 2026-01 | D14: =SUMIFS(业务数据统计!F:F,业务数据统计!U:U,A14,业务数据统计!H:H,"是") -> 26.6 | E14: =_xlfn.XLOOKUP(A14,业务数据统计!U:U,业务数据统计!V:V,"") -> 营销二部 | G14: 销售五部 | H14: =SUMIFS(D:D,B:B,G14) -> 907.85
A15: 陈巧玲 | B15: =_xlfn.XLOOKUP(E15,部门!A:A,部门!B:B) -> 销售三部 | C15: =$F$1 -> 2026-01 | D15: =SUMIFS(业务数据统计!F:F,业务数据统计!U:U,A15,业务数据统计!H:H,"是") -> 4 | E15: =_xlfn.XLOOKUP(A15,业务数据统计!U:U,业务数据统计!V:V,"") -> 营销三部 | G15: 销售一部 | H15: =SUMIFS(D:D,B:B,G15) -> 34.1
A16: 段泽明 | B16: =_xlfn.XLOOKUP(E16,部门!A:A,部门!B:B) -> 销售三部 | C16: =$F$1 -> 2026-01 | D16: =SUMIFS(业务数据统计!F:F,业务数据统计!U:U,A16,业务数据统计!H:H,"是") -> 61.9 | E16: =_xlfn.XLOOKUP(A16,业务数据统计!U:U,业务数据统计!V:V,"") -> 营销三部
A17: 吴丽辉 | B17: =_xlfn.XLOOKUP(E17,部门!A:A,部门!B:B) -> 销售三部 | C17: =$F$1 -> 2026-01 | D17: =SUMIFS(业务数据统计!F:F,业务数据统计!U:U,A17,业务数据统计!H:H,"是") -> 49.1 | E17: =_xlfn.XLOOKUP(A17,业务数据统计!U:U,业务数据统计!V:V,"") -> 营销三部
A18: 李凤 | B18: =_xlfn.XLOOKUP(E18,部门!A:A,部门!B:B) -> 销售四部 | C18: =$F$1 -> 2026-01 | D18: =SUMIFS(业务数据统计!F:F,业务数据统计!U:U,A18,业务数据统计!H:H,"是") -> 22.9 | E18: =_xlfn.XLOOKUP(A18,业务数据统计!U:U,业务数据统计!V:V,"") -> 营销四部
A19: 汪祺 | B19: =_xlfn.XLOOKUP(E19,部门!A:A,部门!B:B) -> 销售二部 | C19: =$F$1 -> 2026-01 | D19: =SUMIFS(业务数据统计!F:F,业务数据统计!U:U,A19,业务数据统计!H:H,"是") -> 8 | E19: =_xlfn.XLOOKUP(A19,业务数据统计!U:U,业务数据统计!V:V,"") -> 营销二部 | H19: =SUM(H8:H17) -> 2341.95
A20: 朱杰 | B20: =_xlfn.XLOOKUP(E20,部门!A:A,部门!B:B) -> 销售四部 | C20: =$F$1 -> 2026-01 | D20: =SUMIFS(业务数据统计!F:F,业务数据统计!U:U,A20,业务数据统计!H:H,"是") -> 80.8 | E20: =_xlfn.XLOOKUP(A20,业务数据统计!U:U,业务数据统计!V:V,"") -> 营销四部
A21: 邓健群 | B21: =_xlfn.XLOOKUP(E21,部门!A:A,部门!B:B) -> 销售三部 | C21: =$F$1 -> 2026-01 | D21: =SUMIFS(业务数据统计!F:F,业务数据统计!U:U,A21,业务数据统计!H:H,"是") -> 15.8 | E21: =_xlfn.XLOOKUP(A21,业务数据统计!U:U,业务数据统计!V:V,"") -> 营销三部
A22: 王岩岩 | B22: =_xlfn.XLOOKUP(E22,部门!A:A,部门!B:B) -> 销售四部 | C22: =$F$1 -> 2026-01 | D22: =SUMIFS(业务数据统计!F:F,业务数据统计!U:U,A22,业务数据统计!H:H,"是") -> 28 | E22: =_xlfn.XLOOKUP(A22,业务数据统计!U:U,业务数据统计!V:V,"") -> 营销四部
A23: 李得胜 | B23: =_xlfn.XLOOKUP(E23,部门!A:A,部门!B:B) -> 销售四部 | C23: =$F$1 -> 2026-01 | D23: =SUMIFS(业务数据统计!F:F,业务数据统计!U:U,A23,业务数据统计!H:H,"是") -> 4 | E23: =_xlfn.XLOOKUP(A23,业务数据统计!U:U,业务数据统计!V:V,"") -> 营销四部
A24: 小飞侠 | B24: =_xlfn.XLOOKUP(E24,部门!A:A,部门!B:B) -> 销售五部 | C24: =$F$1 -> 2026-01 | D24: =SUMIFS(业务数据统计!F:F,业务数据统计!U:U,A24,业务数据统计!H:H,"是") -> 73.45 | E24: =_xlfn.XLOOKUP(A24,业务数据统计!U:U,业务数据统计!V:V,"") -> 营销五部
A25: 许会彦 | B25: =_xlfn.XLOOKUP(E25,部门!A:A,部门!B:B) -> 销售四部 | C25: =$F$1 -> 2026-01 | D25: =SUMIFS(业务数据统计!F:F,业务数据统计!U:U,A25,业务数据统计!H:H,"是") -> 2 | E25: =_xlfn.XLOOKUP(A25,业务数据统计!U:U,业务数据统计!V:V,"") -> 营销四部
A26: 余雨婕 | B26: =_xlfn.XLOOKUP(E26,部门!A:A,部门!B:B) -> 销售四部 | C26: =$F$1 -> 2026-01 | D26: =SUMIFS(业务数据统计!F:F,业务数据统计!U:U,A26,业务数据统计!H:H,"是") -> 14 | E26: =_xlfn.XLOOKUP(A26,业务数据统计!U:U,业务数据统计!V:V,"") -> 营销四部
A27: 左宗伟 | B27: =_xlfn.XLOOKUP(E27,部门!A:A,部门!B:B) -> 销售四部 | C27: =$F$1 -> 2026-01 | D27: =SUMIFS(业务数据统计!F:F,业务数据统计!U:U,A27,业务数据统计!H:H,"是") -> 50.6 | E27: =_xlfn.XLOOKUP(A27,业务数据统计!U:U,业务数据统计!V:V,"") -> 营销四部
A28: 张俊合 | B28: =_xlfn.XLOOKUP(E28,部门!A:A,部门!B:B) -> 销售五部 | C28: =$F$1 -> 2026-01 | D28: =SUMIFS(业务数据统计!F:F,业务数据统计!U:U,A28,业务数据统计!H:H,"是") -> 35.3 | E28: =_xlfn.XLOOKUP(A28,业务数据统计!U:U,业务数据统计!V:V,"") -> 营销五部
A29: 杨胜东 | B29: =_xlfn.XLOOKUP(E29,部门!A:A,部门!B:B) -> 销售四部 | C29: =$F$1 -> 2026-01 | D29: =SUMIFS(业务数据统计!F:F,业务数据统计!U:U,A29,业务数据统计!H:H,"是") -> 11.6 | E29: =_xlfn.XLOOKUP(A29,业务数据统计!U:U,业务数据统计!V:V,"") -> 营销四部
A30: 陈炎 | B30: =_xlfn.XLOOKUP(E30,部门!A:A,部门!B:B) -> 销售二部 | C30: =$F$1 -> 2026-01 | D30: =SUMIFS(业务数据统计!F:F,业务数据统计!U:U,A30,业务数据统计!H:H,"是") -> 12 | E30: =_xlfn.XLOOKUP(A30,业务数据统计!U:U,业务数据统计!V:V,"") -> 营销二部
A31: 付乐航 | B31: =_xlfn.XLOOKUP(E31,部门!A:A,部门!B:B) -> 销售五部 | C31: =$F$1 -> 2026-01 | D31: =SUMIFS(业务数据统计!F:F,业务数据统计!U:U,A31,业务数据统计!H:H,"是") -> 119.9 | E31: =_xlfn.XLOOKUP(A31,业务数据统计!U:U,业务数据统计!V:V,"") -> 营销五部
... A63: 魏心华 | B63: =_xlfn.XLOOKUP(E63,部门!A:A,部门!B:B) -> 销售四部 | C63: =$F$1 -> 2026-01 | D63: =SUMIFS(业务数据统计!F:F,业务数据统计!U:U,A63,业务数据统计!H:H,"是") -> 4 | E63: =_xlfn.XLOOKUP(A63,业务数据统计!U:U,业务数据统计!V:V,"") -> 营销四部
A64: 合计： | D64: =SUM(D3:D63) -> 2341.95

Sheet 部门
A1: 业务员部门 | B1: 部门
A2: KA部-亮剑队 | B2: KA部
A3: KA部-一组长 | B3: KA部
A4: KA部-群英队 | B4: KA部
A5: 北苑-业务员 | B5: 北苑
A6: 北苑-业务员-陈伟 | B6: 北苑
A7: 北苑-业务员-冯玉勋 | B7: 北苑
A8: 广州分公司-业务员 | B8: 广州
A9: 广州分公司-业务员(曹深研) | B9: 广州
A10: 广州分公司-业务员(练思强) | B10: 广州
A11: 广州分公司-业务员(周源伟) | B11: 广州
A12: 广州分公司-业务员-马井贝 | B12: 广州
... A22: 深圳-业务员-刘薇 | B22: 深圳
A23: 深圳-直客-业务员 | B23: 深圳 | E23: 、
A24: 深圳-直客-坂田 | B24: 深圳
A25: 拓展部-飓风队 | B25: 拓展部-直客
A26: 吴慧俊
A27: 下王公司-业务员 | B27: 下王
A28: 下王公司-总经理 | B28: 下王
A29: 下王-业务员 | B29: 下王
A30: 销售二部-第一队 | B30: 销售二部
A31: 销售二部-昊阳队 | B31: 销售二部
A32: 销售二部-烈火队 | B32: 销售二部
A33: 销售二部-野狼队 | B33: 销售二部
A34: 销售三部-战狼队 | B34: 销售三部
A35: 销售三部-主管 | B35: 销售三部
A36: 销售一部-火箭队 | B36: 销售一部
A37: 销售一部-迈凯伦队 | B37: 销售一部
A38: 销售一部-王炸队 | B38: 销售一部
... A90: 四部KA客服 | B90: 销售四部

Sheet 无崖子提成
B4: 渠道客服提成明细表
B5: 客服系统名 | C5: 姓名 | D5: 票数 | E5: 提成系数 | F5: 应发提成 | G5: 特殊事项扣除 | H5: 实发工资
B6: 无崖子 | C6: 江雯 | D6: =COUNTIFS(业务数据统计!B:B,B6,业务数据统计!AA:AA,"正常走货") -> 756 | E6: 1 | F6: =D6*E6 -> 756 | H6: =F6-G6 -> 756
B9: 2025年6月6日起江雯开始有提成
